<?xml version='1.0'?>
<sdf version='1.6'>
  <model name='fake_uav2'>
  <static>1</static>
    <!-- sunray body -->
    <link name='base_link'>
      <pose>0 0 0 0 0 0</pose>
      <inertial>
        <pose>0 0 0 0 0 0</pose>
        <mass>1.0</mass>
        <inertia>
          <ixx>0.0085</ixx>
          <ixy>0</ixy>
          <ixz>0</ixz>
          <iyy>0.0085</iyy>
          <iyz>0</iyz>
          <izz>0.012</izz>
        </inertia>
      </inertial>
      <visual name='base_link_inertia_visual'>
        <pose>0 0 0 0 0 -1.57</pose>
        <geometry>
          <mesh>
            <scale>0.03 0.03 0.03</scale>
            <uri>model://fake_uav2/meshes/sunray.stl</uri>
          </mesh>
        </geometry>
        <material>
          <script>
            <name>Gazebo/DarkGrey</name>
            <uri>file://media/materials/scripts/gazebo.material</uri>
          </script>
        </material>
      </visual>
      <gravity>1</gravity>
      <velocity_decay/>
      <self_collide>0</self_collide>
    </link>
    <link name='rotor_0'>
			<pose>0.065 -0.065 -0.025 0 0 0</pose>
      <inertial>
        <pose>0 0 0 0 0 0</pose>
        <mass>0.005</mass>
        <inertia>
          <ixx>9.75e-07</ixx>
          <ixy>0</ixy>
          <ixz>0</ixz>
          <iyy>0.000173104</iyy>
          <iyz>0</iyz>
          <izz>0.000174004</izz>
        </inertia>
      </inertial>
      <visual name='rotor_0_visual'>
        <pose>0 0 0 1.57 0 0</pose>
        <geometry>
          <mesh>
            <scale>0.03 0.03 0.03</scale>
            <uri>model://fake_uav2/meshes/sunray_cw.stl</uri>
          </mesh>
        </geometry>
        <material>
          <script>
            <name>Gazebo/Red</name>
            <uri>file://media/materials/scripts/gazebo.material</uri>
          </script>
        </material>
      </visual>
      <gravity>1</gravity>
      <velocity_decay/>
      <self_collide>0</self_collide>
    </link>
    <joint name='rotor_0_joint' type='revolute'>
      <child>rotor_0</child>
      <parent>base_link</parent>
      <axis>
        <xyz>0 0 1</xyz>
        <limit>
          <lower>-1e+16</lower>
          <upper>1e+16</upper>
        </limit>
        <dynamics>
          <spring_reference>0</spring_reference>
          <spring_stiffness>0</spring_stiffness>
        </dynamics>
        <use_parent_model_frame>1</use_parent_model_frame>
      </axis>
    </joint>
    <link name='rotor_1'>
			<pose>-0.065 0.065 -0.025 0 0 0</pose>
      <inertial>
        <pose>0 0 0 0 0 0</pose>
        <mass>0.005</mass>
        <inertia>
          <ixx>9.75e-07</ixx>
          <ixy>0</ixy>
          <ixz>0</ixz>
          <iyy>0.000173104</iyy>
          <iyz>0</iyz>
          <izz>0.000174004</izz>
        </inertia>
      </inertial>
      <visual name='rotor_1_visual'>
        <pose>0 0 0 1.57 0 0</pose>
        <geometry>
          <mesh>
            <scale>0.03 0.03 0.03</scale>
            <uri>model://fake_uav2/meshes/sunray_cw.stl</uri>
          </mesh>
        </geometry>
        <material>
          <script>
            <name>Gazebo/Blue</name>
            <uri>file://media/materials/scripts/gazebo.material</uri>
          </script>
        </material>
      </visual>
      <gravity>1</gravity>
      <velocity_decay/>
      <self_collide>0</self_collide>
    </link>
    <joint name='rotor_1_joint' type='revolute'>
      <child>rotor_1</child>
      <parent>base_link</parent>
      <axis>
        <xyz>0 0 1</xyz>
        <limit>
          <lower>-1e+16</lower>
          <upper>1e+16</upper>
        </limit>
        <dynamics>
          <spring_reference>0</spring_reference>
          <spring_stiffness>0</spring_stiffness>
        </dynamics>
        <use_parent_model_frame>1</use_parent_model_frame>
      </axis>
    </joint>
    <link name='rotor_2'>
			<pose>0.065 0.065 -0.025 0 0 0</pose>
      <inertial>
        <pose>0 0 0 0 0 0</pose>
        <mass>0.005</mass>
        <inertia>
          <ixx>9.75e-07</ixx>
          <ixy>0</ixy>
          <ixz>0</ixz>
          <iyy>0.000173104</iyy>
          <iyz>0</iyz>
          <izz>0.000174004</izz>
        </inertia>
      </inertial>
      <visual name='rotor_2_visual'>
        <pose>0 0 0 1.57 0 0</pose>
        <geometry>
          <mesh>
            <scale>0.03 0.03 0.03</scale>
            <uri>model://fake_uav2/meshes/sunray_cw.stl</uri>
          </mesh>
        </geometry>
        <material>
          <script>
            <name>Gazebo/Red</name>
            <uri>file://media/materials/scripts/gazebo.material</uri>
          </script>
        </material>
      </visual>
      <gravity>1</gravity>
      <velocity_decay/>
      <self_collide>0</self_collide>
    </link>
    <joint name='rotor_2_joint' type='revolute'>
      <child>rotor_2</child>
      <parent>base_link</parent>
      <axis>
        <xyz>0 0 1</xyz>
        <limit>
          <lower>-1e+16</lower>
          <upper>1e+16</upper>
        </limit>
        <dynamics>
          <spring_reference>0</spring_reference>
          <spring_stiffness>0</spring_stiffness>
        </dynamics>
        <use_parent_model_frame>1</use_parent_model_frame>
      </axis>
    </joint>
    <link name='rotor_3'>
			<pose>-0.065 -0.065 -0.025 0 0 0</pose>
      <inertial>
        <pose>0 0 0 0 0 0</pose>
        <mass>0.005</mass>
        <inertia>
          <ixx>9.75e-07</ixx>
          <ixy>0</ixy>
          <ixz>0</ixz>
          <iyy>0.000173104</iyy>
          <iyz>0</iyz>
          <izz>0.000174004</izz>
        </inertia>
      </inertial>
      <visual name='rotor_3_visual'>
        <pose>0 0 0 1.57 0 0</pose>
        <geometry>
          <mesh>
            <scale>0.03 0.03 0.03</scale>
            <uri>model://fake_uav2/meshes/sunray_cw.stl</uri>
          </mesh>
        </geometry>
        <material>
          <script>
            <name>Gazebo/Blue</name>
            <uri>file://media/materials/scripts/gazebo.material</uri>
          </script>
        </material>
      </visual>
      <gravity>1</gravity>
      <velocity_decay/>
      <self_collide>0</self_collide>
    </link>
    <joint name='rotor_3_joint' type='revolute'>
      <child>rotor_3</child>
      <parent>base_link</parent>
      <axis>
        <xyz>0 0 1</xyz>
        <limit>
          <lower>-1e+16</lower>
          <upper>1e+16</upper>
        </limit>
        <dynamics>
          <spring_reference>0</spring_reference>
          <spring_stiffness>0</spring_stiffness>
        </dynamics>
        <use_parent_model_frame>1</use_parent_model_frame>
      </axis>
    </joint>

    <!-- plugins: libgazebo_ros_p3d -->
    <!-- 发布真值,模拟vicon系统 -->
    <plugin name="p3d_base_controller" filename="libgazebo_ros_p3d.so">
      <alwaysOn>true</alwaysOn>
      <updateRate>50.0</updateRate>
      <bodyName>base_link</bodyName>
      <topicName>/uav_2/gazebo_pose</topicName>
      <gaussianNoise>0.00</gaussianNoise>
      <frameName>world</frameName>
      <xyzOffsets>0 0 0</xyzOffsets>
      <rpyOffsets>0 0 0</rpyOffsets>
    </plugin>

    <!-- 传感器开始 -->

    <include>
      <uri>model://camera_front</uri> 
      <pose>0.12 0 0.025 0 0 0</pose>
    </include>
    <!-- 前视相机关节 -->
    <joint name="Monocular_front_joint" type="fixed">
      <child>camera_front::Monocular_front_link</child>
      <parent>base_link</parent>
      <axis>
        <xyz>0 0 1</xyz>
        <limit>
          <upper>0</upper>
          <lower>0</lower>
        </limit>
      </axis>
    </joint>

    <include>
      <uri>model://camera_down</uri>
      <pose>-0.01 0 -0.02 0 1.5707963 3.14</pose> <!--位置-->
    </include>
    <!-- 下视相机关节 -->
    <joint name="Monocular_down_joint" type="fixed">
      <child>camera_down::Monocular_down_link</child> <!--子link-->
      <parent>base_link</parent><!--父link-->
      <axis>
        <xyz>0 0 1</xyz><!--xyz标签定义轴的方向，是单位向量，默认值为0 0 1，参考系一般为joint参考系-->
        <limit>
          <upper>0</upper>
          <lower>0</lower>
        </limit>
      </axis>
    </joint>  

    <include>
      <uri>model://livox_mid360</uri>
      <pose>0.036 -0.0155 0.075 0 0 0</pose>
    </include>
    <joint name="mid360_joint" type="fixed">
      <child>livox_mid360::base_link</child>
      <parent>base_link</parent>
      <axis>
        <xyz>0 0 1</xyz>
        <limit>
          <upper>0</upper>
          <lower>0</lower>
        </limit>
      </axis>
    </joint>
  </model>
</sdf>
