<sdf version='1.7'>
  <world name='default'>
    <physics type='ode'>
      <max_step_size>0.001</max_step_size>
      <real_time_update_rate>1000</real_time_update_rate>
      <real_time_factor>1</real_time_factor>
    </physics>
    <model name='ground_plane'>
      <static>1</static>
      <link name='link'>
        <collision name='collision'>
          <geometry>
            <plane>
              <normal>0 0 1</normal>
              <size>100 100</size>
            </plane>
          </geometry>
          <surface>
            <contact>
              <collide_bitmask>65535</collide_bitmask>
              <ode/>
            </contact>
            <friction>
              <ode>
                <mu>100</mu>
                <mu2>50</mu2>
              </ode>
              <torsional>
                <ode/>
              </torsional>
            </friction>
            <bounce/>
          </surface>
          <max_contacts>10</max_contacts>
        </collision>
        <visual name='visual'>
          <cast_shadows>0</cast_shadows>
          <geometry>
            <plane>
              <normal>0 0 1</normal>
              <size>100 100</size>
            </plane>
          </geometry>
          <material>
            <script>
              <uri>file://media/materials/scripts/gazebo.material</uri>
              <name>Gazebo/Grey</name>
            </script>
          </material>
        </visual>
        <self_collide>0</self_collide>
        <enable_wind>0</enable_wind>
        <kinematic>0</kinematic>
      </link>
    </model>
    <light name='sun' type='directional'>
      <cast_shadows>0</cast_shadows>
      <pose>0 0 100 0 -0 0</pose>
      <diffuse>0.8 0.8 0.8 1</diffuse>
      <specular>0.9 0.9 0.9 1</specular>
      <attenuation>
        <range>1000</range>
        <constant>0.9</constant>
        <linear>0.01</linear>
        <quadratic>0.001</quadratic>
      </attenuation>
      <direction>0.2 0.2 -0.9</direction>
      <spot>
        <inner_angle>0</inner_angle>
        <outer_angle>0</outer_angle>
        <falloff>0</falloff>
      </spot>
    </light>
    <model name='uav_1'>
      <frame name='fake_uav1::__model__' attached_to='fake_uav1::base_link'>
        <pose relative_to='__model__'>0 0 0 0 -0 0</pose>
      </frame>
      <static>1</static>
      <link name='fake_uav1::base_link'>
        <pose relative_to='fake_uav1::__model__'>0 0 0 0 -0 0</pose>
        <inertial>
          <pose>0 0 0 0 -0 0</pose>
          <mass>1</mass>
          <inertia>
            <ixx>0.0085</ixx>
            <ixy>0</ixy>
            <ixz>0</ixz>
            <iyy>0.0085</iyy>
            <iyz>0</iyz>
            <izz>0.012</izz>
          </inertia>
        </inertial>
        <visual name='base_link_inertia_visual'>
          <pose>0 0 0 0 0 -1.57</pose>
          <geometry>
            <mesh>
              <scale>0.03 0.03 0.03</scale>
              <uri>model://fake_uav1/meshes/sunray.stl</uri>
            </mesh>
          </geometry>
          <material>
            <script>
              <name>Gazebo/DarkGrey</name>
              <uri>file://media/materials/scripts/gazebo.material</uri>
            </script>
          </material>
        </visual>
        <gravity>1</gravity>
        <velocity_decay/>
        <self_collide>0</self_collide>
        <enable_wind>0</enable_wind>
        <kinematic>0</kinematic>
      </link>
      <link name='fake_uav1::rotor_0'>
        <pose relative_to='fake_uav1::__model__'>0.065 -0.065 -0.025 0 -0 0</pose>
        <inertial>
          <pose>0 0 0 0 -0 0</pose>
          <mass>0.005</mass>
          <inertia>
            <ixx>9.75e-07</ixx>
            <ixy>0</ixy>
            <ixz>0</ixz>
            <iyy>0.000173104</iyy>
            <iyz>0</iyz>
            <izz>0.000174004</izz>
          </inertia>
        </inertial>
        <visual name='rotor_0_visual'>
          <pose>0 0 0 1.57 -0 0</pose>
          <geometry>
            <mesh>
              <scale>0.03 0.03 0.03</scale>
              <uri>model://fake_uav1/meshes/sunray_cw.stl</uri>
            </mesh>
          </geometry>
          <material>
            <script>
              <name>Gazebo/Red</name>
              <uri>file://media/materials/scripts/gazebo.material</uri>
            </script>
          </material>
        </visual>
        <gravity>1</gravity>
        <velocity_decay/>
        <self_collide>0</self_collide>
        <enable_wind>0</enable_wind>
        <kinematic>0</kinematic>
      </link>
      <joint name='fake_uav1::rotor_0_joint' type='revolute'>
        <child>fake_uav1::rotor_0</child>
        <parent>fake_uav1::base_link</parent>
        <axis>
          <xyz expressed_in='fake_uav1::__model__'>0 0 1</xyz>
          <limit>
            <lower>-1e+16</lower>
            <upper>1e+16</upper>
          </limit>
          <dynamics>
            <spring_reference>0</spring_reference>
            <spring_stiffness>0</spring_stiffness>
          </dynamics>
        </axis>
      </joint>
      <link name='fake_uav1::rotor_1'>
        <pose relative_to='fake_uav1::__model__'>-0.065 0.065 -0.025 0 -0 0</pose>
        <inertial>
          <pose>0 0 0 0 -0 0</pose>
          <mass>0.005</mass>
          <inertia>
            <ixx>9.75e-07</ixx>
            <ixy>0</ixy>
            <ixz>0</ixz>
            <iyy>0.000173104</iyy>
            <iyz>0</iyz>
            <izz>0.000174004</izz>
          </inertia>
        </inertial>
        <visual name='rotor_1_visual'>
          <pose>0 0 0 1.57 -0 0</pose>
          <geometry>
            <mesh>
              <scale>0.03 0.03 0.03</scale>
              <uri>model://fake_uav1/meshes/sunray_cw.stl</uri>
            </mesh>
          </geometry>
          <material>
            <script>
              <name>Gazebo/Blue</name>
              <uri>file://media/materials/scripts/gazebo.material</uri>
            </script>
          </material>
        </visual>
        <gravity>1</gravity>
        <velocity_decay/>
        <self_collide>0</self_collide>
        <enable_wind>0</enable_wind>
        <kinematic>0</kinematic>
      </link>
      <joint name='fake_uav1::rotor_1_joint' type='revolute'>
        <child>fake_uav1::rotor_1</child>
        <parent>fake_uav1::base_link</parent>
        <axis>
          <xyz expressed_in='fake_uav1::__model__'>0 0 1</xyz>
          <limit>
            <lower>-1e+16</lower>
            <upper>1e+16</upper>
          </limit>
          <dynamics>
            <spring_reference>0</spring_reference>
            <spring_stiffness>0</spring_stiffness>
          </dynamics>
        </axis>
      </joint>
      <link name='fake_uav1::rotor_2'>
        <pose relative_to='fake_uav1::__model__'>0.065 0.065 -0.025 0 -0 0</pose>
        <inertial>
          <pose>0 0 0 0 -0 0</pose>
          <mass>0.005</mass>
          <inertia>
            <ixx>9.75e-07</ixx>
            <ixy>0</ixy>
            <ixz>0</ixz>
            <iyy>0.000173104</iyy>
            <iyz>0</iyz>
            <izz>0.000174004</izz>
          </inertia>
        </inertial>
        <visual name='rotor_2_visual'>
          <pose>0 0 0 1.57 -0 0</pose>
          <geometry>
            <mesh>
              <scale>0.03 0.03 0.03</scale>
              <uri>model://fake_uav1/meshes/sunray_cw.stl</uri>
            </mesh>
          </geometry>
          <material>
            <script>
              <name>Gazebo/Red</name>
              <uri>file://media/materials/scripts/gazebo.material</uri>
            </script>
          </material>
        </visual>
        <gravity>1</gravity>
        <velocity_decay/>
        <self_collide>0</self_collide>
        <enable_wind>0</enable_wind>
        <kinematic>0</kinematic>
      </link>
      <joint name='fake_uav1::rotor_2_joint' type='revolute'>
        <child>fake_uav1::rotor_2</child>
        <parent>fake_uav1::base_link</parent>
        <axis>
          <xyz expressed_in='fake_uav1::__model__'>0 0 1</xyz>
          <limit>
            <lower>-1e+16</lower>
            <upper>1e+16</upper>
          </limit>
          <dynamics>
            <spring_reference>0</spring_reference>
            <spring_stiffness>0</spring_stiffness>
          </dynamics>
        </axis>
      </joint>
      <link name='fake_uav1::rotor_3'>
        <pose relative_to='fake_uav1::__model__'>-0.065 -0.065 -0.025 0 -0 0</pose>
        <inertial>
          <pose>0 0 0 0 -0 0</pose>
          <mass>0.005</mass>
          <inertia>
            <ixx>9.75e-07</ixx>
            <ixy>0</ixy>
            <ixz>0</ixz>
            <iyy>0.000173104</iyy>
            <iyz>0</iyz>
            <izz>0.000174004</izz>
          </inertia>
        </inertial>
        <visual name='rotor_3_visual'>
          <pose>0 0 0 1.57 -0 0</pose>
          <geometry>
            <mesh>
              <scale>0.03 0.03 0.03</scale>
              <uri>model://fake_uav1/meshes/sunray_cw.stl</uri>
            </mesh>
          </geometry>
          <material>
            <script>
              <name>Gazebo/Blue</name>
              <uri>file://media/materials/scripts/gazebo.material</uri>
            </script>
          </material>
        </visual>
        <gravity>1</gravity>
        <velocity_decay/>
        <self_collide>0</self_collide>
        <enable_wind>0</enable_wind>
        <kinematic>0</kinematic>
      </link>
      <joint name='fake_uav1::rotor_3_joint' type='revolute'>
        <child>fake_uav1::rotor_3</child>
        <parent>fake_uav1::base_link</parent>
        <axis>
          <xyz expressed_in='fake_uav1::__model__'>0 0 1</xyz>
          <limit>
            <lower>-1e+16</lower>
            <upper>1e+16</upper>
          </limit>
          <dynamics>
            <spring_reference>0</spring_reference>
            <spring_stiffness>0</spring_stiffness>
          </dynamics>
        </axis>
      </joint>
      <plugin name='p3d_base_controller' filename='libgazebo_ros_p3d.so'>
        <alwaysOn>1</alwaysOn>
        <updateRate>50.0</updateRate>
        <bodyName>fake_uav1::base_link</bodyName>
        <topicName>/uav_1/gazebo_pose</topicName>
        <gaussianNoise>0.00</gaussianNoise>
        <frameName>world</frameName>
        <xyzOffsets>0 0 0</xyzOffsets>
        <rpyOffsets>0 0 0</rpyOffsets>
      </plugin>
      <frame name='fake_uav1::camera_front::__model__' attached_to='fake_uav1::camera_front::Monocular_front_link'>
        <pose relative_to='fake_uav1::__model__'>0.12 0 0.025 0 -0 0</pose>
      </frame>
      <link name='fake_uav1::camera_front::Monocular_front_link'>
        <inertial>
          <mass>0.001</mass>
          <inertia>
            <ixx>1e-06</ixx>
            <ixy>0</ixy>
            <ixz>0</ixz>
            <iyy>1e-06</iyy>
            <iyz>0</iyz>
            <izz>1e-06</izz>
          </inertia>
        </inertial>
        <visual name='visual'>
          <geometry>
            <box>
              <size>0.01 0.01 0.01</size>
            </box>
          </geometry>
        </visual>
        <collision name='collision'>
          <pose>0 0 0 0 -0 0</pose>
          <geometry>
            <box>
              <size>0.01 0.01 0.01</size>
            </box>
          </geometry>
          <max_contacts>10</max_contacts>
          <surface>
            <contact>
              <ode/>
            </contact>
            <bounce/>
            <friction>
              <torsional>
                <ode/>
              </torsional>
              <ode/>
            </friction>
          </surface>
        </collision>
        <sensor name='camera' type='camera'>
          <camera name='__default__'>
            <horizontal_fov>1.239</horizontal_fov>
            <image>
              <width>640</width>
              <height>480</height>
            </image>
            <clip>
              <near>0.1</near>
              <far>100</far>
            </clip>
            <noise>
              <type>gaussian</type>
              <mean>0</mean>
              <stddev>0.001</stddev>
            </noise>
          </camera>
          <always_on>1</always_on>
          <update_rate>30</update_rate>
          <visualize>0</visualize>
          <plugin name='camera_plugin' filename='libgazebo_ros_camera.so'>
            <robotNamespace/>
            <alwaysOn>1</alwaysOn>
            <imageTopicName>image_raw</imageTopicName>
            <cameraInfoTopicName>camera_info</cameraInfoTopicName>
            <updateRate>30.0</updateRate>
            <cameraName>monocular_front</cameraName>
            <frameName>/monocular_front_link</frameName>
            <CxPrime>320</CxPrime>
            <Cx>320</Cx>
            <Cy>240</Cy>
            <hackBaseline>0</hackBaseline>
            <focalLength>448.710659</focalLength>
            <distortionK1>0.0</distortionK1>
            <distortionK2>0.0</distortionK2>
            <distortionK3>0.0</distortionK3>
            <distortionT1>0.0</distortionT1>
            <distortionT2>0.0</distortionT2>
          </plugin>
        </sensor>
        <self_collide>0</self_collide>
        <kinematic>0</kinematic>
        <pose relative_to='fake_uav1::camera_front::__model__'>0 0 0 0 -0 0</pose>
        <enable_wind>0</enable_wind>
      </link>
      <joint name='fake_uav1::Monocular_front_joint' type='fixed'>
        <child>fake_uav1::camera_front::Monocular_front_link</child>
        <parent>fake_uav1::base_link</parent>
        <axis>
          <xyz>0 0 1</xyz>
          <limit>
            <upper>0</upper>
            <lower>0</lower>
          </limit>
        </axis>
      </joint>
      <frame name='fake_uav1::camera_down::__model__' attached_to='fake_uav1::camera_down::Monocular_down_link'>
        <pose relative_to='fake_uav1::__model__'>-0.01 0 -0.02 0.001593 1.57079 3.14159</pose>
      </frame>
      <link name='fake_uav1::camera_down::Monocular_down_link'>
        <inertial>
          <mass>0.001</mass>
          <inertia>
            <ixx>1e-06</ixx>
            <ixy>0</ixy>
            <ixz>0</ixz>
            <iyy>1e-06</iyy>
            <iyz>0</iyz>
            <izz>1e-06</izz>
          </inertia>
        </inertial>
        <visual name='visual'>
          <geometry>
            <box>
              <size>0.01 0.01 0.01</size>
            </box>
          </geometry>
        </visual>
        <collision name='collision'>
          <pose>0 0 0 0 -0 0</pose>
          <geometry>
            <box>
              <size>0.01 0.01 0.01</size>
            </box>
          </geometry>
          <max_contacts>10</max_contacts>
          <surface>
            <contact>
              <ode/>
            </contact>
            <bounce/>
            <friction>
              <torsional>
                <ode/>
              </torsional>
              <ode/>
            </friction>
          </surface>
        </collision>
        <sensor name='camera' type='camera'>
          <camera name='__default__'>
            <horizontal_fov>1.239</horizontal_fov>
            <image>
              <width>640</width>
              <height>480</height>
            </image>
            <clip>
              <near>0.1</near>
              <far>100</far>
            </clip>
            <noise>
              <type>gaussian</type>
              <mean>0</mean>
              <stddev>0.001</stddev>
            </noise>
          </camera>
          <always_on>1</always_on>
          <update_rate>30</update_rate>
          <visualize>0</visualize>
          <plugin name='camera_plugin' filename='libgazebo_ros_camera.so'>
            <robotNamespace/>
            <alwaysOn>1</alwaysOn>
            <imageTopicName>image_raw</imageTopicName>
            <cameraInfoTopicName>camera_info</cameraInfoTopicName>
            <updateRate>30.0</updateRate>
            <cameraName>monocular_down</cameraName>
            <frameName>/monocular_down_link</frameName>
            <CxPrime>320</CxPrime>
            <Cx>320</Cx>
            <Cy>240</Cy>
            <hackBaseline>0</hackBaseline>
            <focalLength>448.710659</focalLength>
            <distortionK1>0.0</distortionK1>
            <distortionK2>0.0</distortionK2>
            <distortionK3>0.0</distortionK3>
            <distortionT1>0.0</distortionT1>
            <distortionT2>0.0</distortionT2>
          </plugin>
        </sensor>
        <self_collide>0</self_collide>
        <kinematic>0</kinematic>
        <pose relative_to='fake_uav1::camera_down::__model__'>0 0 0 0 -0 0</pose>
        <enable_wind>0</enable_wind>
      </link>
      <joint name='fake_uav1::Monocular_down_joint' type='fixed'>
        <child>fake_uav1::camera_down::Monocular_down_link</child>
        <parent>fake_uav1::base_link</parent>
        <axis>
          <xyz>0 0 1</xyz>
          <limit>
            <upper>0</upper>
            <lower>0</lower>
          </limit>
        </axis>
      </joint>
      <frame name='fake_uav1::livox_mid360::__model__' attached_to='fake_uav1::livox_mid360::base_link'>
        <pose relative_to='fake_uav1::__model__'>0.036 -0.0155 0.075 0 -0 0</pose>
      </frame>
      <link name='fake_uav1::livox_mid360::base_link'>
        <pose relative_to='fake_uav1::livox_mid360::__model__'>0 0 0 0 -0 0</pose>
        <inertial>
          <pose>0 0 0 0 -0 0</pose>
          <mass>0.01</mass>
          <inertia>
            <ixx>0.0001</ixx>
            <ixy>0</ixy>
            <ixz>0</ixz>
            <iyy>0.0001</iyy>
            <iyz>0</iyz>
            <izz>0.0001</izz>
          </inertia>
        </inertial>
        <collision name='collision'>
          <pose>0 0 0 1.57 -0 3.14159</pose>
          <geometry>
            <mesh>
              <scale>1.2 1.2 1.2</scale>
              <uri>model://livox_mid360/meshes/test2.dae</uri>
            </mesh>
          </geometry>
          <max_contacts>10</max_contacts>
          <surface>
            <contact>
              <ode/>
            </contact>
            <bounce/>
            <friction>
              <torsional>
                <ode/>
              </torsional>
              <ode/>
            </friction>
          </surface>
        </collision>
        <visual name='link_fixed_joint_lump__oasis_300_visual'>
          <pose>0 0 0 1.57 -0 3.14159</pose>
          <geometry>
            <mesh>
              <scale>1.2 1.2 1.2</scale>
              <uri>model://livox_mid360/meshes/test2.dae</uri>
            </mesh>
          </geometry>
        </visual>
        <sensor name='laser_livox' type='ray'>
          <pose>0 0 0.1 0 -0 0</pose>
          <visualize>0</visualize>
          <always_on>1</always_on>
          <update_rate>10</update_rate>
          <plugin name='gazebo_ros_laser_controller' filename='liblivox_laser_simulation.so'>
            <ray>
              <scan>
                <horizontal>
                  <samples>100</samples>
                  <resolution>1</resolution>
                  <min_angle>-3.1415926535897931</min_angle>
                  <max_angle>3.1415926535897931</max_angle>
                </horizontal>
                <vertical>
                  <samples>50</samples>
                  <resolution>1</resolution>
                  <min_angle>-3.1415926535897931</min_angle>
                  <max_angle>3.1415926535897931</max_angle>
                </vertical>
              </scan>
              <range>
                <min>0.4</min>
                <max>40</max>
                <resolution>1</resolution>
              </range>
              <noise>
                <type>gaussian</type>
                <mean>0.0</mean>
                <stddev>0.0</stddev>
              </noise>
            </ray>
            <visualize>0</visualize>
            <samples>20000</samples>
            <downsample>4</downsample>
            <csv_file_name>mid360-real-centr.csv</csv_file_name>
            <publish_pointcloud_type>1</publish_pointcloud_type>
            <ros_topic>livox/lidar</ros_topic>
            <frameName>fake_uav1::livox_mid360::base_link</frameName>
          </plugin>
          <ray>
            <scan>
              <horizontal>
                <samples>640</samples>
                <resolution>1</resolution>
                <min_angle>0</min_angle>
                <max_angle>0</max_angle>
              </horizontal>
              <vertical>
                <samples>1</samples>
                <min_angle>0</min_angle>
                <max_angle>0</max_angle>
              </vertical>
            </scan>
            <range>
              <min>0</min>
              <max>0</max>
            </range>
          </ray>
        </sensor>
        <sensor name='imu_sensor' type='imu'>
          <always_on>1</always_on>
          <update_rate>100</update_rate>
          <visualize>0</visualize>
          <topic>livox/imu</topic>
          <plugin name='imu_plugin' filename='libgazebo_ros_imu_sensor.so'>
            <topicName>livox/imu</topicName>
            <bodyName>fake_uav1::livox_mid360::base_link</bodyName>
            <updateRateHZ>100.0</updateRateHZ>
            <gaussianNoise>0.0</gaussianNoise>
            <xyzOffset>0 0 0</xyzOffset>
            <rpyOffset>0 0 0</rpyOffset>
            <frameName>fake_uav1::livox_mid360::base_link</frameName>
          </plugin>
          <pose>0 0 0 0 -0 0</pose>
          <imu/>
        </sensor>
        <self_collide>0</self_collide>
        <enable_wind>0</enable_wind>
        <kinematic>0</kinematic>
      </link>
      <joint name='fake_uav1::mid360_joint' type='fixed'>
        <child>fake_uav1::livox_mid360::base_link</child>
        <parent>fake_uav1::base_link</parent>
        <axis>
          <xyz>0 0 1</xyz>
          <limit>
            <upper>0</upper>
            <lower>0</lower>
          </limit>
        </axis>
      </joint>
    </model>
    <model name='uav_2'>
      <frame name='fake_uav2::__model__' attached_to='fake_uav2::base_link'>
        <pose relative_to='__model__'>0 0 0 0 -0 0</pose>
      </frame>
      <static>1</static>
      <link name='fake_uav2::base_link'>
        <pose relative_to='fake_uav2::__model__'>0 0 0 0 -0 0</pose>
        <inertial>
          <pose>0 0 0 0 -0 0</pose>
          <mass>1</mass>
          <inertia>
            <ixx>0.0085</ixx>
            <ixy>0</ixy>
            <ixz>0</ixz>
            <iyy>0.0085</iyy>
            <iyz>0</iyz>
            <izz>0.012</izz>
          </inertia>
        </inertial>
        <visual name='base_link_inertia_visual'>
          <pose>0 0 0 0 0 -1.57</pose>
          <geometry>
            <mesh>
              <scale>0.03 0.03 0.03</scale>
              <uri>model://fake_uav2/meshes/sunray.stl</uri>
            </mesh>
          </geometry>
          <material>
            <script>
              <name>Gazebo/DarkGrey</name>
              <uri>file://media/materials/scripts/gazebo.material</uri>
            </script>
          </material>
        </visual>
        <gravity>1</gravity>
        <velocity_decay/>
        <self_collide>0</self_collide>
        <enable_wind>0</enable_wind>
        <kinematic>0</kinematic>
      </link>
      <link name='fake_uav2::rotor_0'>
        <pose relative_to='fake_uav2::__model__'>0.065 -0.065 -0.025 0 -0 0</pose>
        <inertial>
          <pose>0 0 0 0 -0 0</pose>
          <mass>0.005</mass>
          <inertia>
            <ixx>9.75e-07</ixx>
            <ixy>0</ixy>
            <ixz>0</ixz>
            <iyy>0.000173104</iyy>
            <iyz>0</iyz>
            <izz>0.000174004</izz>
          </inertia>
        </inertial>
        <visual name='rotor_0_visual'>
          <pose>0 0 0 1.57 -0 0</pose>
          <geometry>
            <mesh>
              <scale>0.03 0.03 0.03</scale>
              <uri>model://fake_uav2/meshes/sunray_cw.stl</uri>
            </mesh>
          </geometry>
          <material>
            <script>
              <name>Gazebo/Red</name>
              <uri>file://media/materials/scripts/gazebo.material</uri>
            </script>
          </material>
        </visual>
        <gravity>1</gravity>
        <velocity_decay/>
        <self_collide>0</self_collide>
        <enable_wind>0</enable_wind>
        <kinematic>0</kinematic>
      </link>
      <joint name='fake_uav2::rotor_0_joint' type='revolute'>
        <child>fake_uav2::rotor_0</child>
        <parent>fake_uav2::base_link</parent>
        <axis>
          <xyz expressed_in='fake_uav2::__model__'>0 0 1</xyz>
          <limit>
            <lower>-1e+16</lower>
            <upper>1e+16</upper>
          </limit>
          <dynamics>
            <spring_reference>0</spring_reference>
            <spring_stiffness>0</spring_stiffness>
          </dynamics>
        </axis>
      </joint>
      <link name='fake_uav2::rotor_1'>
        <pose relative_to='fake_uav2::__model__'>-0.065 0.065 -0.025 0 -0 0</pose>
        <inertial>
          <pose>0 0 0 0 -0 0</pose>
          <mass>0.005</mass>
          <inertia>
            <ixx>9.75e-07</ixx>
            <ixy>0</ixy>
            <ixz>0</ixz>
            <iyy>0.000173104</iyy>
            <iyz>0</iyz>
            <izz>0.000174004</izz>
          </inertia>
        </inertial>
        <visual name='rotor_1_visual'>
          <pose>0 0 0 1.57 -0 0</pose>
          <geometry>
            <mesh>
              <scale>0.03 0.03 0.03</scale>
              <uri>model://fake_uav2/meshes/sunray_cw.stl</uri>
            </mesh>
          </geometry>
          <material>
            <script>
              <name>Gazebo/Blue</name>
              <uri>file://media/materials/scripts/gazebo.material</uri>
            </script>
          </material>
        </visual>
        <gravity>1</gravity>
        <velocity_decay/>
        <self_collide>0</self_collide>
        <enable_wind>0</enable_wind>
        <kinematic>0</kinematic>
      </link>
      <joint name='fake_uav2::rotor_1_joint' type='revolute'>
        <child>fake_uav2::rotor_1</child>
        <parent>fake_uav2::base_link</parent>
        <axis>
          <xyz expressed_in='fake_uav2::__model__'>0 0 1</xyz>
          <limit>
            <lower>-1e+16</lower>
            <upper>1e+16</upper>
          </limit>
          <dynamics>
            <spring_reference>0</spring_reference>
            <spring_stiffness>0</spring_stiffness>
          </dynamics>
        </axis>
      </joint>
      <link name='fake_uav2::rotor_2'>
        <pose relative_to='fake_uav2::__model__'>0.065 0.065 -0.025 0 -0 0</pose>
        <inertial>
          <pose>0 0 0 0 -0 0</pose>
          <mass>0.005</mass>
          <inertia>
            <ixx>9.75e-07</ixx>
            <ixy>0</ixy>
            <ixz>0</ixz>
            <iyy>0.000173104</iyy>
            <iyz>0</iyz>
            <izz>0.000174004</izz>
          </inertia>
        </inertial>
        <visual name='rotor_2_visual'>
          <pose>0 0 0 1.57 -0 0</pose>
          <geometry>
            <mesh>
              <scale>0.03 0.03 0.03</scale>
              <uri>model://fake_uav2/meshes/sunray_cw.stl</uri>
            </mesh>
          </geometry>
          <material>
            <script>
              <name>Gazebo/Red</name>
              <uri>file://media/materials/scripts/gazebo.material</uri>
            </script>
          </material>
        </visual>
        <gravity>1</gravity>
        <velocity_decay/>
        <self_collide>0</self_collide>
        <enable_wind>0</enable_wind>
        <kinematic>0</kinematic>
      </link>
      <joint name='fake_uav2::rotor_2_joint' type='revolute'>
        <child>fake_uav2::rotor_2</child>
        <parent>fake_uav2::base_link</parent>
        <axis>
          <xyz expressed_in='fake_uav2::__model__'>0 0 1</xyz>
          <limit>
            <lower>-1e+16</lower>
            <upper>1e+16</upper>
          </limit>
          <dynamics>
            <spring_reference>0</spring_reference>
            <spring_stiffness>0</spring_stiffness>
          </dynamics>
        </axis>
      </joint>
      <link name='fake_uav2::rotor_3'>
        <pose relative_to='fake_uav2::__model__'>-0.065 -0.065 -0.025 0 -0 0</pose>
        <inertial>
          <pose>0 0 0 0 -0 0</pose>
          <mass>0.005</mass>
          <inertia>
            <ixx>9.75e-07</ixx>
            <ixy>0</ixy>
            <ixz>0</ixz>
            <iyy>0.000173104</iyy>
            <iyz>0</iyz>
            <izz>0.000174004</izz>
          </inertia>
        </inertial>
        <visual name='rotor_3_visual'>
          <pose>0 0 0 1.57 -0 0</pose>
          <geometry>
            <mesh>
              <scale>0.03 0.03 0.03</scale>
              <uri>model://fake_uav2/meshes/sunray_cw.stl</uri>
            </mesh>
          </geometry>
          <material>
            <script>
              <name>Gazebo/Blue</name>
              <uri>file://media/materials/scripts/gazebo.material</uri>
            </script>
          </material>
        </visual>
        <gravity>1</gravity>
        <velocity_decay/>
        <self_collide>0</self_collide>
        <enable_wind>0</enable_wind>
        <kinematic>0</kinematic>
      </link>
      <joint name='fake_uav2::rotor_3_joint' type='revolute'>
        <child>fake_uav2::rotor_3</child>
        <parent>fake_uav2::base_link</parent>
        <axis>
          <xyz expressed_in='fake_uav2::__model__'>0 0 1</xyz>
          <limit>
            <lower>-1e+16</lower>
            <upper>1e+16</upper>
          </limit>
          <dynamics>
            <spring_reference>0</spring_reference>
            <spring_stiffness>0</spring_stiffness>
          </dynamics>
        </axis>
      </joint>
      <plugin name='p3d_base_controller' filename='libgazebo_ros_p3d.so'>
        <alwaysOn>1</alwaysOn>
        <updateRate>50.0</updateRate>
        <bodyName>fake_uav2::base_link</bodyName>
        <topicName>/uav_2/gazebo_pose</topicName>
        <gaussianNoise>0.00</gaussianNoise>
        <frameName>world</frameName>
        <xyzOffsets>0 0 0</xyzOffsets>
        <rpyOffsets>0 0 0</rpyOffsets>
      </plugin>
      <frame name='fake_uav2::camera_front::__model__' attached_to='fake_uav2::camera_front::Monocular_front_link'>
        <pose relative_to='fake_uav2::__model__'>0.12 0 0.025 0 -0 0</pose>
      </frame>
      <link name='fake_uav2::camera_front::Monocular_front_link'>
        <inertial>
          <mass>0.001</mass>
          <inertia>
            <ixx>1e-06</ixx>
            <ixy>0</ixy>
            <ixz>0</ixz>
            <iyy>1e-06</iyy>
            <iyz>0</iyz>
            <izz>1e-06</izz>
          </inertia>
        </inertial>
        <visual name='visual'>
          <geometry>
            <box>
              <size>0.01 0.01 0.01</size>
            </box>
          </geometry>
        </visual>
        <collision name='collision'>
          <pose>0 0 0 0 -0 0</pose>
          <geometry>
            <box>
              <size>0.01 0.01 0.01</size>
            </box>
          </geometry>
          <max_contacts>10</max_contacts>
          <surface>
            <contact>
              <ode/>
            </contact>
            <bounce/>
            <friction>
              <torsional>
                <ode/>
              </torsional>
              <ode/>
            </friction>
          </surface>
        </collision>
        <sensor name='camera' type='camera'>
          <camera name='__default__'>
            <horizontal_fov>1.239</horizontal_fov>
            <image>
              <width>640</width>
              <height>480</height>
            </image>
            <clip>
              <near>0.1</near>
              <far>100</far>
            </clip>
            <noise>
              <type>gaussian</type>
              <mean>0</mean>
              <stddev>0.001</stddev>
            </noise>
          </camera>
          <always_on>1</always_on>
          <update_rate>30</update_rate>
          <visualize>0</visualize>
          <plugin name='camera_plugin' filename='libgazebo_ros_camera.so'>
            <robotNamespace/>
            <alwaysOn>1</alwaysOn>
            <imageTopicName>image_raw</imageTopicName>
            <cameraInfoTopicName>camera_info</cameraInfoTopicName>
            <updateRate>30.0</updateRate>
            <cameraName>monocular_front</cameraName>
            <frameName>/monocular_front_link</frameName>
            <CxPrime>320</CxPrime>
            <Cx>320</Cx>
            <Cy>240</Cy>
            <hackBaseline>0</hackBaseline>
            <focalLength>448.710659</focalLength>
            <distortionK1>0.0</distortionK1>
            <distortionK2>0.0</distortionK2>
            <distortionK3>0.0</distortionK3>
            <distortionT1>0.0</distortionT1>
            <distortionT2>0.0</distortionT2>
          </plugin>
        </sensor>
        <self_collide>0</self_collide>
        <kinematic>0</kinematic>
        <pose relative_to='fake_uav2::camera_front::__model__'>0 0 0 0 -0 0</pose>
        <enable_wind>0</enable_wind>
      </link>
      <joint name='fake_uav2::Monocular_front_joint' type='fixed'>
        <child>fake_uav2::camera_front::Monocular_front_link</child>
        <parent>fake_uav2::base_link</parent>
        <axis>
          <xyz>0 0 1</xyz>
          <limit>
            <upper>0</upper>
            <lower>0</lower>
          </limit>
        </axis>
      </joint>
      <frame name='fake_uav2::camera_down::__model__' attached_to='fake_uav2::camera_down::Monocular_down_link'>
        <pose relative_to='fake_uav2::__model__'>-0.01 0 -0.02 0.001593 1.57079 3.14159</pose>
      </frame>
      <link name='fake_uav2::camera_down::Monocular_down_link'>
        <inertial>
          <mass>0.001</mass>
          <inertia>
            <ixx>1e-06</ixx>
            <ixy>0</ixy>
            <ixz>0</ixz>
            <iyy>1e-06</iyy>
            <iyz>0</iyz>
            <izz>1e-06</izz>
          </inertia>
        </inertial>
        <visual name='visual'>
          <geometry>
            <box>
              <size>0.01 0.01 0.01</size>
            </box>
          </geometry>
        </visual>
        <collision name='collision'>
          <pose>0 0 0 0 -0 0</pose>
          <geometry>
            <box>
              <size>0.01 0.01 0.01</size>
            </box>
          </geometry>
          <max_contacts>10</max_contacts>
          <surface>
            <contact>
              <ode/>
            </contact>
            <bounce/>
            <friction>
              <torsional>
                <ode/>
              </torsional>
              <ode/>
            </friction>
          </surface>
        </collision>
        <sensor name='camera' type='camera'>
          <camera name='__default__'>
            <horizontal_fov>1.239</horizontal_fov>
            <image>
              <width>640</width>
              <height>480</height>
            </image>
            <clip>
              <near>0.1</near>
              <far>100</far>
            </clip>
            <noise>
              <type>gaussian</type>
              <mean>0</mean>
              <stddev>0.001</stddev>
            </noise>
          </camera>
          <always_on>1</always_on>
          <update_rate>30</update_rate>
          <visualize>0</visualize>
          <plugin name='camera_plugin' filename='libgazebo_ros_camera.so'>
            <robotNamespace/>
            <alwaysOn>1</alwaysOn>
            <imageTopicName>image_raw</imageTopicName>
            <cameraInfoTopicName>camera_info</cameraInfoTopicName>
            <updateRate>30.0</updateRate>
            <cameraName>monocular_down</cameraName>
            <frameName>/monocular_down_link</frameName>
            <CxPrime>320</CxPrime>
            <Cx>320</Cx>
            <Cy>240</Cy>
            <hackBaseline>0</hackBaseline>
            <focalLength>448.710659</focalLength>
            <distortionK1>0.0</distortionK1>
            <distortionK2>0.0</distortionK2>
            <distortionK3>0.0</distortionK3>
            <distortionT1>0.0</distortionT1>
            <distortionT2>0.0</distortionT2>
          </plugin>
        </sensor>
        <self_collide>0</self_collide>
        <kinematic>0</kinematic>
        <pose relative_to='fake_uav2::camera_down::__model__'>0 0 0 0 -0 0</pose>
        <enable_wind>0</enable_wind>
      </link>
      <joint name='fake_uav2::Monocular_down_joint' type='fixed'>
        <child>fake_uav2::camera_down::Monocular_down_link</child>
        <parent>fake_uav2::base_link</parent>
        <axis>
          <xyz>0 0 1</xyz>
          <limit>
            <upper>0</upper>
            <lower>0</lower>
          </limit>
        </axis>
      </joint>
      <frame name='fake_uav2::livox_mid360::__model__' attached_to='fake_uav2::livox_mid360::base_link'>
        <pose relative_to='fake_uav2::__model__'>0.036 -0.0155 0.075 0 -0 0</pose>
      </frame>
      <link name='fake_uav2::livox_mid360::base_link'>
        <pose relative_to='fake_uav2::livox_mid360::__model__'>0 0 0 0 -0 0</pose>
        <inertial>
          <pose>0 0 0 0 -0 0</pose>
          <mass>0.01</mass>
          <inertia>
            <ixx>0.0001</ixx>
            <ixy>0</ixy>
            <ixz>0</ixz>
            <iyy>0.0001</iyy>
            <iyz>0</iyz>
            <izz>0.0001</izz>
          </inertia>
        </inertial>
        <collision name='collision'>
          <pose>0 0 0 1.57 -0 3.14159</pose>
          <geometry>
            <mesh>
              <scale>1.2 1.2 1.2</scale>
              <uri>model://livox_mid360/meshes/test2.dae</uri>
            </mesh>
          </geometry>
          <max_contacts>10</max_contacts>
          <surface>
            <contact>
              <ode/>
            </contact>
            <bounce/>
            <friction>
              <torsional>
                <ode/>
              </torsional>
              <ode/>
            </friction>
          </surface>
        </collision>
        <visual name='link_fixed_joint_lump__oasis_300_visual'>
          <pose>0 0 0 1.57 -0 3.14159</pose>
          <geometry>
            <mesh>
              <scale>1.2 1.2 1.2</scale>
              <uri>model://livox_mid360/meshes/test2.dae</uri>
            </mesh>
          </geometry>
        </visual>
        <sensor name='laser_livox' type='ray'>
          <pose>0 0 0.1 0 -0 0</pose>
          <visualize>0</visualize>
          <always_on>1</always_on>
          <update_rate>10</update_rate>
          <plugin name='gazebo_ros_laser_controller' filename='liblivox_laser_simulation.so'>
            <ray>
              <scan>
                <horizontal>
                  <samples>100</samples>
                  <resolution>1</resolution>
                  <min_angle>-3.1415926535897931</min_angle>
                  <max_angle>3.1415926535897931</max_angle>
                </horizontal>
                <vertical>
                  <samples>50</samples>
                  <resolution>1</resolution>
                  <min_angle>-3.1415926535897931</min_angle>
                  <max_angle>3.1415926535897931</max_angle>
                </vertical>
              </scan>
              <range>
                <min>0.4</min>
                <max>40</max>
                <resolution>1</resolution>
              </range>
              <noise>
                <type>gaussian</type>
                <mean>0.0</mean>
                <stddev>0.0</stddev>
              </noise>
            </ray>
            <visualize>0</visualize>
            <samples>20000</samples>
            <downsample>4</downsample>
            <csv_file_name>mid360-real-centr.csv</csv_file_name>
            <publish_pointcloud_type>1</publish_pointcloud_type>
            <ros_topic>livox/lidar</ros_topic>
            <frameName>fake_uav2::livox_mid360::base_link</frameName>
          </plugin>
          <ray>
            <scan>
              <horizontal>
                <samples>640</samples>
                <resolution>1</resolution>
                <min_angle>0</min_angle>
                <max_angle>0</max_angle>
              </horizontal>
              <vertical>
                <samples>1</samples>
                <min_angle>0</min_angle>
                <max_angle>0</max_angle>
              </vertical>
            </scan>
            <range>
              <min>0</min>
              <max>0</max>
            </range>
          </ray>
        </sensor>
        <sensor name='imu_sensor' type='imu'>
          <always_on>1</always_on>
          <update_rate>100</update_rate>
          <visualize>0</visualize>
          <topic>livox/imu</topic>
          <plugin name='imu_plugin' filename='libgazebo_ros_imu_sensor.so'>
            <topicName>livox/imu</topicName>
            <bodyName>fake_uav2::livox_mid360::base_link</bodyName>
            <updateRateHZ>100.0</updateRateHZ>
            <gaussianNoise>0.0</gaussianNoise>
            <xyzOffset>0 0 0</xyzOffset>
            <rpyOffset>0 0 0</rpyOffset>
            <frameName>fake_uav2::livox_mid360::base_link</frameName>
          </plugin>
          <pose>0 0 0 0 -0 0</pose>
          <imu/>
        </sensor>
        <self_collide>0</self_collide>
        <enable_wind>0</enable_wind>
        <kinematic>0</kinematic>
      </link>
      <joint name='fake_uav2::mid360_joint' type='fixed'>
        <child>fake_uav2::livox_mid360::base_link</child>
        <parent>fake_uav2::base_link</parent>
        <axis>
          <xyz>0 0 1</xyz>
          <limit>
            <upper>0</upper>
            <lower>0</lower>
          </limit>
        </axis>
      </joint>
    </model>
    <model name='uav_3'>
      <frame name='fake_uav3::__model__' attached_to='fake_uav3::base_link'>
        <pose relative_to='__model__'>0 0 0 0 -0 0</pose>
      </frame>
      <static>1</static>
      <link name='fake_uav3::base_link'>
        <pose relative_to='fake_uav3::__model__'>0 0 0 0 -0 0</pose>
        <inertial>
          <pose>0 0 0 0 -0 0</pose>
          <mass>1</mass>
          <inertia>
            <ixx>0.0085</ixx>
            <ixy>0</ixy>
            <ixz>0</ixz>
            <iyy>0.0085</iyy>
            <iyz>0</iyz>
            <izz>0.012</izz>
          </inertia>
        </inertial>
        <visual name='base_link_inertia_visual'>
          <pose>0 0 0 0 0 -1.57</pose>
          <geometry>
            <mesh>
              <scale>0.03 0.03 0.03</scale>
              <uri>model://fake_uav3/meshes/sunray.stl</uri>
            </mesh>
          </geometry>
          <material>
            <script>
              <name>Gazebo/DarkGrey</name>
              <uri>file://media/materials/scripts/gazebo.material</uri>
            </script>
          </material>
        </visual>
        <gravity>1</gravity>
        <velocity_decay/>
        <self_collide>0</self_collide>
        <enable_wind>0</enable_wind>
        <kinematic>0</kinematic>
      </link>
      <link name='fake_uav3::rotor_0'>
        <pose relative_to='fake_uav3::__model__'>0.065 -0.065 -0.025 0 -0 0</pose>
        <inertial>
          <pose>0 0 0 0 -0 0</pose>
          <mass>0.005</mass>
          <inertia>
            <ixx>9.75e-07</ixx>
            <ixy>0</ixy>
            <ixz>0</ixz>
            <iyy>0.000173104</iyy>
            <iyz>0</iyz>
            <izz>0.000174004</izz>
          </inertia>
        </inertial>
        <visual name='rotor_0_visual'>
          <pose>0 0 0 1.57 -0 0</pose>
          <geometry>
            <mesh>
              <scale>0.03 0.03 0.03</scale>
              <uri>model://fake_uav3/meshes/sunray_cw.stl</uri>
            </mesh>
          </geometry>
          <material>
            <script>
              <name>Gazebo/Red</name>
              <uri>file://media/materials/scripts/gazebo.material</uri>
            </script>
          </material>
        </visual>
        <gravity>1</gravity>
        <velocity_decay/>
        <self_collide>0</self_collide>
        <enable_wind>0</enable_wind>
        <kinematic>0</kinematic>
      </link>
      <joint name='fake_uav3::rotor_0_joint' type='revolute'>
        <child>fake_uav3::rotor_0</child>
        <parent>fake_uav3::base_link</parent>
        <axis>
          <xyz expressed_in='fake_uav3::__model__'>0 0 1</xyz>
          <limit>
            <lower>-1e+16</lower>
            <upper>1e+16</upper>
          </limit>
          <dynamics>
            <spring_reference>0</spring_reference>
            <spring_stiffness>0</spring_stiffness>
          </dynamics>
        </axis>
      </joint>
      <link name='fake_uav3::rotor_1'>
        <pose relative_to='fake_uav3::__model__'>-0.065 0.065 -0.025 0 -0 0</pose>
        <inertial>
          <pose>0 0 0 0 -0 0</pose>
          <mass>0.005</mass>
          <inertia>
            <ixx>9.75e-07</ixx>
            <ixy>0</ixy>
            <ixz>0</ixz>
            <iyy>0.000173104</iyy>
            <iyz>0</iyz>
            <izz>0.000174004</izz>
          </inertia>
        </inertial>
        <visual name='rotor_1_visual'>
          <pose>0 0 0 1.57 -0 0</pose>
          <geometry>
            <mesh>
              <scale>0.03 0.03 0.03</scale>
              <uri>model://fake_uav3/meshes/sunray_cw.stl</uri>
            </mesh>
          </geometry>
          <material>
            <script>
              <name>Gazebo/Blue</name>
              <uri>file://media/materials/scripts/gazebo.material</uri>
            </script>
          </material>
        </visual>
        <gravity>1</gravity>
        <velocity_decay/>
        <self_collide>0</self_collide>
        <enable_wind>0</enable_wind>
        <kinematic>0</kinematic>
      </link>
      <joint name='fake_uav3::rotor_1_joint' type='revolute'>
        <child>fake_uav3::rotor_1</child>
        <parent>fake_uav3::base_link</parent>
        <axis>
          <xyz expressed_in='fake_uav3::__model__'>0 0 1</xyz>
          <limit>
            <lower>-1e+16</lower>
            <upper>1e+16</upper>
          </limit>
          <dynamics>
            <spring_reference>0</spring_reference>
            <spring_stiffness>0</spring_stiffness>
          </dynamics>
        </axis>
      </joint>
      <link name='fake_uav3::rotor_2'>
        <pose relative_to='fake_uav3::__model__'>0.065 0.065 -0.025 0 -0 0</pose>
        <inertial>
          <pose>0 0 0 0 -0 0</pose>
          <mass>0.005</mass>
          <inertia>
            <ixx>9.75e-07</ixx>
            <ixy>0</ixy>
            <ixz>0</ixz>
            <iyy>0.000173104</iyy>
            <iyz>0</iyz>
            <izz>0.000174004</izz>
          </inertia>
        </inertial>
        <visual name='rotor_2_visual'>
          <pose>0 0 0 1.57 -0 0</pose>
          <geometry>
            <mesh>
              <scale>0.03 0.03 0.03</scale>
              <uri>model://fake_uav3/meshes/sunray_cw.stl</uri>
            </mesh>
          </geometry>
          <material>
            <script>
              <name>Gazebo/Red</name>
              <uri>file://media/materials/scripts/gazebo.material</uri>
            </script>
          </material>
        </visual>
        <gravity>1</gravity>
        <velocity_decay/>
        <self_collide>0</self_collide>
        <enable_wind>0</enable_wind>
        <kinematic>0</kinematic>
      </link>
      <joint name='fake_uav3::rotor_2_joint' type='revolute'>
        <child>fake_uav3::rotor_2</child>
        <parent>fake_uav3::base_link</parent>
        <axis>
          <xyz expressed_in='fake_uav3::__model__'>0 0 1</xyz>
          <limit>
            <lower>-1e+16</lower>
            <upper>1e+16</upper>
          </limit>
          <dynamics>
            <spring_reference>0</spring_reference>
            <spring_stiffness>0</spring_stiffness>
          </dynamics>
        </axis>
      </joint>
      <link name='fake_uav3::rotor_3'>
        <pose relative_to='fake_uav3::__model__'>-0.065 -0.065 -0.025 0 -0 0</pose>
        <inertial>
          <pose>0 0 0 0 -0 0</pose>
          <mass>0.005</mass>
          <inertia>
            <ixx>9.75e-07</ixx>
            <ixy>0</ixy>
            <ixz>0</ixz>
            <iyy>0.000173104</iyy>
            <iyz>0</iyz>
            <izz>0.000174004</izz>
          </inertia>
        </inertial>
        <visual name='rotor_3_visual'>
          <pose>0 0 0 1.57 -0 0</pose>
          <geometry>
            <mesh>
              <scale>0.03 0.03 0.03</scale>
              <uri>model://fake_uav3/meshes/sunray_cw.stl</uri>
            </mesh>
          </geometry>
          <material>
            <script>
              <name>Gazebo/Blue</name>
              <uri>file://media/materials/scripts/gazebo.material</uri>
            </script>
          </material>
        </visual>
        <gravity>1</gravity>
        <velocity_decay/>
        <self_collide>0</self_collide>
        <enable_wind>0</enable_wind>
        <kinematic>0</kinematic>
      </link>
      <joint name='fake_uav3::rotor_3_joint' type='revolute'>
        <child>fake_uav3::rotor_3</child>
        <parent>fake_uav3::base_link</parent>
        <axis>
          <xyz expressed_in='fake_uav3::__model__'>0 0 1</xyz>
          <limit>
            <lower>-1e+16</lower>
            <upper>1e+16</upper>
          </limit>
          <dynamics>
            <spring_reference>0</spring_reference>
            <spring_stiffness>0</spring_stiffness>
          </dynamics>
        </axis>
      </joint>
      <plugin name='p3d_base_controller' filename='libgazebo_ros_p3d.so'>
        <alwaysOn>1</alwaysOn>
        <updateRate>50.0</updateRate>
        <bodyName>fake_uav3::base_link</bodyName>
        <topicName>/uav_3/gazebo_pose</topicName>
        <gaussianNoise>0.00</gaussianNoise>
        <frameName>world</frameName>
        <xyzOffsets>0 0 0</xyzOffsets>
        <rpyOffsets>0 0 0</rpyOffsets>
      </plugin>
      <frame name='fake_uav3::camera_front::__model__' attached_to='fake_uav3::camera_front::Monocular_front_link'>
        <pose relative_to='fake_uav3::__model__'>0.12 0 0.025 0 -0 0</pose>
      </frame>
      <link name='fake_uav3::camera_front::Monocular_front_link'>
        <inertial>
          <mass>0.001</mass>
          <inertia>
            <ixx>1e-06</ixx>
            <ixy>0</ixy>
            <ixz>0</ixz>
            <iyy>1e-06</iyy>
            <iyz>0</iyz>
            <izz>1e-06</izz>
          </inertia>
        </inertial>
        <visual name='visual'>
          <geometry>
            <box>
              <size>0.01 0.01 0.01</size>
            </box>
          </geometry>
        </visual>
        <collision name='collision'>
          <pose>0 0 0 0 -0 0</pose>
          <geometry>
            <box>
              <size>0.01 0.01 0.01</size>
            </box>
          </geometry>
          <max_contacts>10</max_contacts>
          <surface>
            <contact>
              <ode/>
            </contact>
            <bounce/>
            <friction>
              <torsional>
                <ode/>
              </torsional>
              <ode/>
            </friction>
          </surface>
        </collision>
        <sensor name='camera' type='camera'>
          <camera name='__default__'>
            <horizontal_fov>1.239</horizontal_fov>
            <image>
              <width>640</width>
              <height>480</height>
            </image>
            <clip>
              <near>0.1</near>
              <far>100</far>
            </clip>
            <noise>
              <type>gaussian</type>
              <mean>0</mean>
              <stddev>0.001</stddev>
            </noise>
          </camera>
          <always_on>1</always_on>
          <update_rate>30</update_rate>
          <visualize>0</visualize>
          <plugin name='camera_plugin' filename='libgazebo_ros_camera.so'>
            <robotNamespace/>
            <alwaysOn>1</alwaysOn>
            <imageTopicName>image_raw</imageTopicName>
            <cameraInfoTopicName>camera_info</cameraInfoTopicName>
            <updateRate>30.0</updateRate>
            <cameraName>monocular_front</cameraName>
            <frameName>/monocular_front_link</frameName>
            <CxPrime>320</CxPrime>
            <Cx>320</Cx>
            <Cy>240</Cy>
            <hackBaseline>0</hackBaseline>
            <focalLength>448.710659</focalLength>
            <distortionK1>0.0</distortionK1>
            <distortionK2>0.0</distortionK2>
            <distortionK3>0.0</distortionK3>
            <distortionT1>0.0</distortionT1>
            <distortionT2>0.0</distortionT2>
          </plugin>
        </sensor>
        <self_collide>0</self_collide>
        <kinematic>0</kinematic>
        <pose relative_to='fake_uav3::camera_front::__model__'>0 0 0 0 -0 0</pose>
        <enable_wind>0</enable_wind>
      </link>
      <joint name='fake_uav3::Monocular_front_joint' type='fixed'>
        <child>fake_uav3::camera_front::Monocular_front_link</child>
        <parent>fake_uav3::base_link</parent>
        <axis>
          <xyz>0 0 1</xyz>
          <limit>
            <upper>0</upper>
            <lower>0</lower>
          </limit>
        </axis>
      </joint>
      <frame name='fake_uav3::camera_down::__model__' attached_to='fake_uav3::camera_down::Monocular_down_link'>
        <pose relative_to='fake_uav3::__model__'>-0.01 0 -0.02 0.001593 1.57079 3.14159</pose>
      </frame>
      <link name='fake_uav3::camera_down::Monocular_down_link'>
        <inertial>
          <mass>0.001</mass>
          <inertia>
            <ixx>1e-06</ixx>
            <ixy>0</ixy>
            <ixz>0</ixz>
            <iyy>1e-06</iyy>
            <iyz>0</iyz>
            <izz>1e-06</izz>
          </inertia>
        </inertial>
        <visual name='visual'>
          <geometry>
            <box>
              <size>0.01 0.01 0.01</size>
            </box>
          </geometry>
        </visual>
        <collision name='collision'>
          <pose>0 0 0 0 -0 0</pose>
          <geometry>
            <box>
              <size>0.01 0.01 0.01</size>
            </box>
          </geometry>
          <max_contacts>10</max_contacts>
          <surface>
            <contact>
              <ode/>
            </contact>
            <bounce/>
            <friction>
              <torsional>
                <ode/>
              </torsional>
              <ode/>
            </friction>
          </surface>
        </collision>
        <sensor name='camera' type='camera'>
          <camera name='__default__'>
            <horizontal_fov>1.239</horizontal_fov>
            <image>
              <width>640</width>
              <height>480</height>
            </image>
            <clip>
              <near>0.1</near>
              <far>100</far>
            </clip>
            <noise>
              <type>gaussian</type>
              <mean>0</mean>
              <stddev>0.001</stddev>
            </noise>
          </camera>
          <always_on>1</always_on>
          <update_rate>30</update_rate>
          <visualize>0</visualize>
          <plugin name='camera_plugin' filename='libgazebo_ros_camera.so'>
            <robotNamespace/>
            <alwaysOn>1</alwaysOn>
            <imageTopicName>image_raw</imageTopicName>
            <cameraInfoTopicName>camera_info</cameraInfoTopicName>
            <updateRate>30.0</updateRate>
            <cameraName>monocular_down</cameraName>
            <frameName>/monocular_down_link</frameName>
            <CxPrime>320</CxPrime>
            <Cx>320</Cx>
            <Cy>240</Cy>
            <hackBaseline>0</hackBaseline>
            <focalLength>448.710659</focalLength>
            <distortionK1>0.0</distortionK1>
            <distortionK2>0.0</distortionK2>
            <distortionK3>0.0</distortionK3>
            <distortionT1>0.0</distortionT1>
            <distortionT2>0.0</distortionT2>
          </plugin>
        </sensor>
        <self_collide>0</self_collide>
        <kinematic>0</kinematic>
        <pose relative_to='fake_uav3::camera_down::__model__'>0 0 0 0 -0 0</pose>
        <enable_wind>0</enable_wind>
      </link>
      <joint name='fake_uav3::Monocular_down_joint' type='fixed'>
        <child>fake_uav3::camera_down::Monocular_down_link</child>
        <parent>fake_uav3::base_link</parent>
        <axis>
          <xyz>0 0 1</xyz>
          <limit>
            <upper>0</upper>
            <lower>0</lower>
          </limit>
        </axis>
      </joint>
      <frame name='fake_uav3::livox_mid360::__model__' attached_to='fake_uav3::livox_mid360::base_link'>
        <pose relative_to='fake_uav3::__model__'>0.036 -0.0155 0.075 0 -0 0</pose>
      </frame>
      <link name='fake_uav3::livox_mid360::base_link'>
        <pose relative_to='fake_uav3::livox_mid360::__model__'>0 0 0 0 -0 0</pose>
        <inertial>
          <pose>0 0 0 0 -0 0</pose>
          <mass>0.01</mass>
          <inertia>
            <ixx>0.0001</ixx>
            <ixy>0</ixy>
            <ixz>0</ixz>
            <iyy>0.0001</iyy>
            <iyz>0</iyz>
            <izz>0.0001</izz>
          </inertia>
        </inertial>
        <collision name='collision'>
          <pose>0 0 0 1.57 -0 3.14159</pose>
          <geometry>
            <mesh>
              <scale>1.2 1.2 1.2</scale>
              <uri>model://livox_mid360/meshes/test2.dae</uri>
            </mesh>
          </geometry>
          <max_contacts>10</max_contacts>
          <surface>
            <contact>
              <ode/>
            </contact>
            <bounce/>
            <friction>
              <torsional>
                <ode/>
              </torsional>
              <ode/>
            </friction>
          </surface>
        </collision>
        <visual name='link_fixed_joint_lump__oasis_300_visual'>
          <pose>0 0 0 1.57 -0 3.14159</pose>
          <geometry>
            <mesh>
              <scale>1.2 1.2 1.2</scale>
              <uri>model://livox_mid360/meshes/test2.dae</uri>
            </mesh>
          </geometry>
        </visual>
        <sensor name='laser_livox' type='ray'>
          <pose>0 0 0.1 0 -0 0</pose>
          <visualize>0</visualize>
          <always_on>1</always_on>
          <update_rate>10</update_rate>
          <plugin name='gazebo_ros_laser_controller' filename='liblivox_laser_simulation.so'>
            <ray>
              <scan>
                <horizontal>
                  <samples>100</samples>
                  <resolution>1</resolution>
                  <min_angle>-3.1415926535897931</min_angle>
                  <max_angle>3.1415926535897931</max_angle>
                </horizontal>
                <vertical>
                  <samples>50</samples>
                  <resolution>1</resolution>
                  <min_angle>-3.1415926535897931</min_angle>
                  <max_angle>3.1415926535897931</max_angle>
                </vertical>
              </scan>
              <range>
                <min>0.4</min>
                <max>40</max>
                <resolution>1</resolution>
              </range>
              <noise>
                <type>gaussian</type>
                <mean>0.0</mean>
                <stddev>0.0</stddev>
              </noise>
            </ray>
            <visualize>0</visualize>
            <samples>20000</samples>
            <downsample>4</downsample>
            <csv_file_name>mid360-real-centr.csv</csv_file_name>
            <publish_pointcloud_type>1</publish_pointcloud_type>
            <ros_topic>livox/lidar</ros_topic>
            <frameName>fake_uav3::livox_mid360::base_link</frameName>
          </plugin>
          <ray>
            <scan>
              <horizontal>
                <samples>640</samples>
                <resolution>1</resolution>
                <min_angle>0</min_angle>
                <max_angle>0</max_angle>
              </horizontal>
              <vertical>
                <samples>1</samples>
                <min_angle>0</min_angle>
                <max_angle>0</max_angle>
              </vertical>
            </scan>
            <range>
              <min>0</min>
              <max>0</max>
            </range>
          </ray>
        </sensor>
        <sensor name='imu_sensor' type='imu'>
          <always_on>1</always_on>
          <update_rate>100</update_rate>
          <visualize>0</visualize>
          <topic>livox/imu</topic>
          <plugin name='imu_plugin' filename='libgazebo_ros_imu_sensor.so'>
            <topicName>livox/imu</topicName>
            <bodyName>fake_uav3::livox_mid360::base_link</bodyName>
            <updateRateHZ>100.0</updateRateHZ>
            <gaussianNoise>0.0</gaussianNoise>
            <xyzOffset>0 0 0</xyzOffset>
            <rpyOffset>0 0 0</rpyOffset>
            <frameName>fake_uav3::livox_mid360::base_link</frameName>
          </plugin>
          <pose>0 0 0 0 -0 0</pose>
          <imu/>
        </sensor>
        <self_collide>0</self_collide>
        <enable_wind>0</enable_wind>
        <kinematic>0</kinematic>
      </link>
      <joint name='fake_uav3::mid360_joint' type='fixed'>
        <child>fake_uav3::livox_mid360::base_link</child>
        <parent>fake_uav3::base_link</parent>
        <axis>
          <xyz>0 0 1</xyz>
          <limit>
            <upper>0</upper>
            <lower>0</lower>
          </limit>
        </axis>
      </joint>
    </model>
    <model name='ugv_1'>
      <frame name='fake_ugv1::__model__' attached_to='fake_ugv1::base_link'>
        <pose relative_to='__model__'>0 0 0 0 -0 0</pose>
      </frame>
      <static>1</static>
      <link name='fake_ugv1::base_link'>
        <pose relative_to='fake_ugv1::__model__'>0 0 0 0 -0 0</pose>
        <visual name='odom_fixed_joint_lump__base_link_visual'>
          <pose>0 0 0 0 -0 0</pose>
          <geometry>
            <mesh>
              <scale>1 1 1</scale>
              <uri>model://fake_ugv1/meshes/chassis_link.STL</uri>
            </mesh>
          </geometry>
          <material>
            <script>
              <name>Gazebo/Grey</name>
              <uri>file://media/materials/scripts/gazebo.material</uri>
            </script>
          </material>
        </visual>
        <visual name='odom_fixed_joint_lump__top_link_visual_1'>
          <pose>0 0 0.114486 0 -0 0</pose>
          <geometry>
            <mesh>
              <scale>1 1 1</scale>
              <uri>model://fake_ugv1/meshes/top_link.STL</uri>
            </mesh>
          </geometry>
          <material>
            <script>
              <name>Gazebo/ZincYellow</name>
              <uri>file://media/materials/scripts/gazebo.material</uri>
            </script>
          </material>
        </visual>
        <visual name='odom_fixed_joint_lump__battery_link_visual_2'>
          <pose>-0.09302 -0.000128 0.114486 0 -0 0</pose>
          <geometry>
            <mesh>
              <scale>1 1 1</scale>
              <uri>model://fake_ugv1/meshes/battery_link.STL</uri>
            </mesh>
          </geometry>
          <material>
            <script>
              <name>Gazebo/FlatBlack</name>
              <uri>file://media/materials/scripts/gazebo.material</uri>
            </script>
          </material>
        </visual>
        <visual name='odom_fixed_joint_lump__housing_link_visual_3'>
          <pose>0.03473 0 0.114486 0 -0 0</pose>
          <geometry>
            <mesh>
              <scale>1 1 1</scale>
              <uri>model://fake_ugv1/meshes/housing_link.STL</uri>
            </mesh>
          </geometry>
          <material>
            <script>
              <name>Gazebo/FlatBlack</name>
              <uri>file://media/materials/scripts/gazebo.material</uri>
            </script>
          </material>
        </visual>
        <visual name='odom_fixed_joint_lump__l_antenna_link_visual_4'>
          <pose>-0.1565 0.0762 0.114486 0 -0 0</pose>
          <geometry>
            <mesh>
              <scale>1 1 1</scale>
              <uri>model://fake_ugv1/meshes/antenna_link.STL</uri>
            </mesh>
          </geometry>
          <material>
            <script>
              <name>Gazebo/FlatBlack</name>
              <uri>file://media/materials/scripts/gazebo.material</uri>
            </script>
          </material>
        </visual>
        <visual name='odom_fixed_joint_lump__r_antenna_link_visual_5'>
          <pose>-0.1565 -0.0762 0.114486 0 -0 0</pose>
          <geometry>
            <mesh>
              <scale>1 1 1</scale>
              <uri>model://fake_ugv1/meshes/antenna_link.STL</uri>
            </mesh>
          </geometry>
          <material>
            <script>
              <name>Gazebo/FlatBlack</name>
              <uri>file://media/materials/scripts/gazebo.material</uri>
            </script>
          </material>
        </visual>
        <gravity>1</gravity>
        <velocity_decay/>
        <self_collide>0</self_collide>
        <enable_wind>0</enable_wind>
        <kinematic>0</kinematic>
      </link>
      <link name='fake_ugv1::lb_wheel_link'>
        <pose relative_to='fake_ugv1::__model__'>-0.15 0.16317 0.0215 0 -0 0</pose>
        <visual name='lb_wheel_link_visual'>
          <pose>0 0 0 0 -0 0</pose>
          <geometry>
            <mesh>
              <scale>1 1 1</scale>
              <uri>model://fake_ugv1/meshes/wheel_link.STL</uri>
            </mesh>
          </geometry>
          <material>
            <script>
              <name>Gazebo/FlatBlack</name>
              <uri>file://media/materials/scripts/gazebo.material</uri>
            </script>
          </material>
        </visual>
        <gravity>1</gravity>
        <velocity_decay/>
        <self_collide>0</self_collide>
        <enable_wind>0</enable_wind>
        <kinematic>0</kinematic>
      </link>
      <joint name='fake_ugv1::lb_wheel_joint' type='revolute'>
        <child>fake_ugv1::lb_wheel_link</child>
        <parent>fake_ugv1::base_link</parent>
        <axis>
          <xyz expressed_in='fake_ugv1::__model__'>0 1 0</xyz>
          <limit>
            <lower>-1e+16</lower>
            <upper>1e+16</upper>
          </limit>
          <dynamics>
            <spring_reference>0</spring_reference>
            <spring_stiffness>0</spring_stiffness>
          </dynamics>
        </axis>
      </joint>
      <link name='fake_ugv1::lf_wheel_link'>
        <pose relative_to='fake_ugv1::__model__'>0.15 0.16317 0.0215 0 -0 0</pose>
        <visual name='lf_wheel_link_visual'>
          <pose>0 0 0 0 -0 0</pose>
          <geometry>
            <mesh>
              <scale>1 1 1</scale>
              <uri>model://fake_ugv1/meshes/wheel_link.STL</uri>
            </mesh>
          </geometry>
          <material>
            <script>
              <name>Gazebo/FlatBlack</name>
              <uri>file://media/materials/scripts/gazebo.material</uri>
            </script>
          </material>
        </visual>
        <gravity>1</gravity>
        <velocity_decay/>
        <self_collide>0</self_collide>
        <enable_wind>0</enable_wind>
        <kinematic>0</kinematic>
      </link>
      <joint name='fake_ugv1::lf_wheel_joint' type='revolute'>
        <child>fake_ugv1::lf_wheel_link</child>
        <parent>fake_ugv1::base_link</parent>
        <axis>
          <xyz expressed_in='fake_ugv1::__model__'>0 1 0</xyz>
          <limit>
            <lower>-1e+16</lower>
            <upper>1e+16</upper>
          </limit>
          <dynamics>
            <spring_reference>0</spring_reference>
            <spring_stiffness>0</spring_stiffness>
          </dynamics>
        </axis>
      </joint>
      <link name='fake_ugv1::rb_wheel_link'>
        <pose relative_to='fake_ugv1::__model__'>-0.15 -0.16317 0.0215 0 -0 0</pose>
        <visual name='rb_wheel_link_visual'>
          <pose>0 0 0 0 -0 0</pose>
          <geometry>
            <mesh>
              <scale>1 1 1</scale>
              <uri>model://fake_ugv1/meshes/wheel_link.STL</uri>
            </mesh>
          </geometry>
          <material>
            <script>
              <name>Gazebo/FlatBlack</name>
              <uri>file://media/materials/scripts/gazebo.material</uri>
            </script>
          </material>
        </visual>
        <gravity>1</gravity>
        <velocity_decay/>
        <self_collide>0</self_collide>
        <enable_wind>0</enable_wind>
        <kinematic>0</kinematic>
      </link>
      <joint name='fake_ugv1::rb_wheel_joint' type='revolute'>
        <child>fake_ugv1::rb_wheel_link</child>
        <parent>fake_ugv1::base_link</parent>
        <axis>
          <xyz expressed_in='fake_ugv1::__model__'>0 1 0</xyz>
          <limit>
            <lower>-1e+16</lower>
            <upper>1e+16</upper>
          </limit>
          <dynamics>
            <spring_reference>0</spring_reference>
            <spring_stiffness>0</spring_stiffness>
          </dynamics>
        </axis>
      </joint>
      <link name='fake_ugv1::rf_wheel_link'>
        <pose relative_to='fake_ugv1::__model__'>0.15 -0.16317 0.0215 0 -0 0</pose>
        <visual name='rf_wheel_link_visual'>
          <pose>0 0 0 0 -0 0</pose>
          <geometry>
            <mesh>
              <scale>1 1 1</scale>
              <uri>model://fake_ugv1/meshes/wheel_link.STL</uri>
            </mesh>
          </geometry>
          <material>
            <script>
              <name>Gazebo/FlatBlack</name>
              <uri>file://media/materials/scripts/gazebo.material</uri>
            </script>
          </material>
        </visual>
        <gravity>1</gravity>
        <velocity_decay/>
        <self_collide>0</self_collide>
        <enable_wind>0</enable_wind>
        <kinematic>0</kinematic>
      </link>
      <joint name='fake_ugv1::rf_wheel_joint' type='revolute'>
        <child>fake_ugv1::rf_wheel_link</child>
        <parent>fake_ugv1::base_link</parent>
        <axis>
          <xyz expressed_in='fake_ugv1::__model__'>0 1 0</xyz>
          <limit>
            <lower>-1e+16</lower>
            <upper>1e+16</upper>
          </limit>
          <dynamics>
            <spring_reference>0</spring_reference>
            <spring_stiffness>0</spring_stiffness>
          </dynamics>
        </axis>
      </joint>
      <plugin name='p3d_base_controller' filename='libgazebo_ros_p3d.so'>
        <alwaysOn>1</alwaysOn>
        <updateRate>50.0</updateRate>
        <bodyName>fake_ugv1::base_link</bodyName>
        <topicName>/ugv_1/gazebo_pose</topicName>
        <gaussianNoise>0.00</gaussianNoise>
        <frameName>world</frameName>
        <xyzOffsets>0 0 0</xyzOffsets>
        <rpyOffsets>0 0 0</rpyOffsets>
      </plugin>
      <frame name='fake_ugv1::camera_front::__model__' attached_to='fake_ugv1::camera_front::Monocular_front_link'>
        <pose relative_to='fake_ugv1::__model__'>0.12 0 0.025 0 -0 0</pose>
      </frame>
      <link name='fake_ugv1::camera_front::Monocular_front_link'>
        <inertial>
          <mass>0.001</mass>
          <inertia>
            <ixx>1e-06</ixx>
            <ixy>0</ixy>
            <ixz>0</ixz>
            <iyy>1e-06</iyy>
            <iyz>0</iyz>
            <izz>1e-06</izz>
          </inertia>
        </inertial>
        <visual name='visual'>
          <geometry>
            <box>
              <size>0.01 0.01 0.01</size>
            </box>
          </geometry>
        </visual>
        <collision name='collision'>
          <pose>0 0 0 0 -0 0</pose>
          <geometry>
            <box>
              <size>0.01 0.01 0.01</size>
            </box>
          </geometry>
          <max_contacts>10</max_contacts>
          <surface>
            <contact>
              <ode/>
            </contact>
            <bounce/>
            <friction>
              <torsional>
                <ode/>
              </torsional>
              <ode/>
            </friction>
          </surface>
        </collision>
        <sensor name='camera' type='camera'>
          <camera name='__default__'>
            <horizontal_fov>1.239</horizontal_fov>
            <image>
              <width>640</width>
              <height>480</height>
            </image>
            <clip>
              <near>0.1</near>
              <far>100</far>
            </clip>
            <noise>
              <type>gaussian</type>
              <mean>0</mean>
              <stddev>0.001</stddev>
            </noise>
          </camera>
          <always_on>1</always_on>
          <update_rate>30</update_rate>
          <visualize>0</visualize>
          <plugin name='camera_plugin' filename='libgazebo_ros_camera.so'>
            <robotNamespace/>
            <alwaysOn>1</alwaysOn>
            <imageTopicName>image_raw</imageTopicName>
            <cameraInfoTopicName>camera_info</cameraInfoTopicName>
            <updateRate>30.0</updateRate>
            <cameraName>monocular_front</cameraName>
            <frameName>/monocular_front_link</frameName>
            <CxPrime>320</CxPrime>
            <Cx>320</Cx>
            <Cy>240</Cy>
            <hackBaseline>0</hackBaseline>
            <focalLength>448.710659</focalLength>
            <distortionK1>0.0</distortionK1>
            <distortionK2>0.0</distortionK2>
            <distortionK3>0.0</distortionK3>
            <distortionT1>0.0</distortionT1>
            <distortionT2>0.0</distortionT2>
          </plugin>
        </sensor>
        <self_collide>0</self_collide>
        <kinematic>0</kinematic>
        <pose relative_to='fake_ugv1::camera_front::__model__'>0 0 0 0 -0 0</pose>
        <enable_wind>0</enable_wind>
      </link>
      <joint name='fake_ugv1::Monocular_front_joint' type='fixed'>
        <child>fake_ugv1::camera_front::Monocular_front_link</child>
        <parent>fake_ugv1::base_link</parent>
        <axis>
          <xyz>0 0 1</xyz>
          <limit>
            <upper>0</upper>
            <lower>0</lower>
          </limit>
        </axis>
      </joint>
    </model>
    <model name='ugv_2'>
      <frame name='fake_ugv2::__model__' attached_to='fake_ugv2::base_link'>
        <pose relative_to='__model__'>0 0 0 0 -0 0</pose>
      </frame>
      <static>1</static>
      <link name='fake_ugv2::base_link'>
        <pose relative_to='fake_ugv2::__model__'>0 0 0 0 -0 0</pose>
        <visual name='odom_fixed_joint_lump__base_link_visual'>
          <pose>0 0 0 0 -0 0</pose>
          <geometry>
            <mesh>
              <scale>1 1 1</scale>
              <uri>model://fake_ugv2/meshes/chassis_link.STL</uri>
            </mesh>
          </geometry>
          <material>
            <script>
              <name>Gazebo/Grey</name>
              <uri>file://media/materials/scripts/gazebo.material</uri>
            </script>
          </material>
        </visual>
        <visual name='odom_fixed_joint_lump__top_link_visual_1'>
          <pose>0 0 0.114486 0 -0 0</pose>
          <geometry>
            <mesh>
              <scale>1 1 1</scale>
              <uri>model://fake_ugv2/meshes/top_link.STL</uri>
            </mesh>
          </geometry>
          <material>
            <script>
              <name>Gazebo/ZincYellow</name>
              <uri>file://media/materials/scripts/gazebo.material</uri>
            </script>
          </material>
        </visual>
        <visual name='odom_fixed_joint_lump__battery_link_visual_2'>
          <pose>-0.09302 -0.000128 0.114486 0 -0 0</pose>
          <geometry>
            <mesh>
              <scale>1 1 1</scale>
              <uri>model://fake_ugv2/meshes/battery_link.STL</uri>
            </mesh>
          </geometry>
          <material>
            <script>
              <name>Gazebo/FlatBlack</name>
              <uri>file://media/materials/scripts/gazebo.material</uri>
            </script>
          </material>
        </visual>
        <visual name='odom_fixed_joint_lump__housing_link_visual_3'>
          <pose>0.03473 0 0.114486 0 -0 0</pose>
          <geometry>
            <mesh>
              <scale>1 1 1</scale>
              <uri>model://fake_ugv2/meshes/housing_link.STL</uri>
            </mesh>
          </geometry>
          <material>
            <script>
              <name>Gazebo/FlatBlack</name>
              <uri>file://media/materials/scripts/gazebo.material</uri>
            </script>
          </material>
        </visual>
        <visual name='odom_fixed_joint_lump__l_antenna_link_visual_4'>
          <pose>-0.1565 0.0762 0.114486 0 -0 0</pose>
          <geometry>
            <mesh>
              <scale>1 1 1</scale>
              <uri>model://fake_ugv2/meshes/antenna_link.STL</uri>
            </mesh>
          </geometry>
          <material>
            <script>
              <name>Gazebo/FlatBlack</name>
              <uri>file://media/materials/scripts/gazebo.material</uri>
            </script>
          </material>
        </visual>
        <visual name='odom_fixed_joint_lump__r_antenna_link_visual_5'>
          <pose>-0.1565 -0.0762 0.114486 0 -0 0</pose>
          <geometry>
            <mesh>
              <scale>1 1 1</scale>
              <uri>model://fake_ugv2/meshes/antenna_link.STL</uri>
            </mesh>
          </geometry>
          <material>
            <script>
              <name>Gazebo/FlatBlack</name>
              <uri>file://media/materials/scripts/gazebo.material</uri>
            </script>
          </material>
        </visual>
        <gravity>1</gravity>
        <velocity_decay/>
        <self_collide>0</self_collide>
        <enable_wind>0</enable_wind>
        <kinematic>0</kinematic>
      </link>
      <link name='fake_ugv2::lb_wheel_link'>
        <pose relative_to='fake_ugv2::__model__'>-0.15 0.16317 0.0215 0 -0 0</pose>
        <visual name='lb_wheel_link_visual'>
          <pose>0 0 0 0 -0 0</pose>
          <geometry>
            <mesh>
              <scale>1 1 1</scale>
              <uri>model://fake_ugv2/meshes/wheel_link.STL</uri>
            </mesh>
          </geometry>
          <material>
            <script>
              <name>Gazebo/FlatBlack</name>
              <uri>file://media/materials/scripts/gazebo.material</uri>
            </script>
          </material>
        </visual>
        <gravity>1</gravity>
        <velocity_decay/>
        <self_collide>0</self_collide>
        <enable_wind>0</enable_wind>
        <kinematic>0</kinematic>
      </link>
      <joint name='fake_ugv2::lb_wheel_joint' type='revolute'>
        <child>fake_ugv2::lb_wheel_link</child>
        <parent>fake_ugv2::base_link</parent>
        <axis>
          <xyz expressed_in='fake_ugv2::__model__'>0 1 0</xyz>
          <limit>
            <lower>-1e+16</lower>
            <upper>1e+16</upper>
          </limit>
          <dynamics>
            <spring_reference>0</spring_reference>
            <spring_stiffness>0</spring_stiffness>
          </dynamics>
        </axis>
      </joint>
      <link name='fake_ugv2::lf_wheel_link'>
        <pose relative_to='fake_ugv2::__model__'>0.15 0.16317 0.0215 0 -0 0</pose>
        <visual name='lf_wheel_link_visual'>
          <pose>0 0 0 0 -0 0</pose>
          <geometry>
            <mesh>
              <scale>1 1 1</scale>
              <uri>model://fake_ugv2/meshes/wheel_link.STL</uri>
            </mesh>
          </geometry>
          <material>
            <script>
              <name>Gazebo/FlatBlack</name>
              <uri>file://media/materials/scripts/gazebo.material</uri>
            </script>
          </material>
        </visual>
        <gravity>1</gravity>
        <velocity_decay/>
        <self_collide>0</self_collide>
        <enable_wind>0</enable_wind>
        <kinematic>0</kinematic>
      </link>
      <joint name='fake_ugv2::lf_wheel_joint' type='revolute'>
        <child>fake_ugv2::lf_wheel_link</child>
        <parent>fake_ugv2::base_link</parent>
        <axis>
          <xyz expressed_in='fake_ugv2::__model__'>0 1 0</xyz>
          <limit>
            <lower>-1e+16</lower>
            <upper>1e+16</upper>
          </limit>
          <dynamics>
            <spring_reference>0</spring_reference>
            <spring_stiffness>0</spring_stiffness>
          </dynamics>
        </axis>
      </joint>
      <link name='fake_ugv2::rb_wheel_link'>
        <pose relative_to='fake_ugv2::__model__'>-0.15 -0.16317 0.0215 0 -0 0</pose>
        <visual name='rb_wheel_link_visual'>
          <pose>0 0 0 0 -0 0</pose>
          <geometry>
            <mesh>
              <scale>1 1 1</scale>
              <uri>model://fake_ugv2/meshes/wheel_link.STL</uri>
            </mesh>
          </geometry>
          <material>
            <script>
              <name>Gazebo/FlatBlack</name>
              <uri>file://media/materials/scripts/gazebo.material</uri>
            </script>
          </material>
        </visual>
        <gravity>1</gravity>
        <velocity_decay/>
        <self_collide>0</self_collide>
        <enable_wind>0</enable_wind>
        <kinematic>0</kinematic>
      </link>
      <joint name='fake_ugv2::rb_wheel_joint' type='revolute'>
        <child>fake_ugv2::rb_wheel_link</child>
        <parent>fake_ugv2::base_link</parent>
        <axis>
          <xyz expressed_in='fake_ugv2::__model__'>0 1 0</xyz>
          <limit>
            <lower>-1e+16</lower>
            <upper>1e+16</upper>
          </limit>
          <dynamics>
            <spring_reference>0</spring_reference>
            <spring_stiffness>0</spring_stiffness>
          </dynamics>
        </axis>
      </joint>
      <link name='fake_ugv2::rf_wheel_link'>
        <pose relative_to='fake_ugv2::__model__'>0.15 -0.16317 0.0215 0 -0 0</pose>
        <visual name='rf_wheel_link_visual'>
          <pose>0 0 0 0 -0 0</pose>
          <geometry>
            <mesh>
              <scale>1 1 1</scale>
              <uri>model://fake_ugv2/meshes/wheel_link.STL</uri>
            </mesh>
          </geometry>
          <material>
            <script>
              <name>Gazebo/FlatBlack</name>
              <uri>file://media/materials/scripts/gazebo.material</uri>
            </script>
          </material>
        </visual>
        <gravity>1</gravity>
        <velocity_decay/>
        <self_collide>0</self_collide>
        <enable_wind>0</enable_wind>
        <kinematic>0</kinematic>
      </link>
      <joint name='fake_ugv2::rf_wheel_joint' type='revolute'>
        <child>fake_ugv2::rf_wheel_link</child>
        <parent>fake_ugv2::base_link</parent>
        <axis>
          <xyz expressed_in='fake_ugv2::__model__'>0 1 0</xyz>
          <limit>
            <lower>-1e+16</lower>
            <upper>1e+16</upper>
          </limit>
          <dynamics>
            <spring_reference>0</spring_reference>
            <spring_stiffness>0</spring_stiffness>
          </dynamics>
        </axis>
      </joint>
      <plugin name='p3d_base_controller' filename='libgazebo_ros_p3d.so'>
        <alwaysOn>1</alwaysOn>
        <updateRate>50.0</updateRate>
        <bodyName>fake_ugv2::base_link</bodyName>
        <topicName>/ugv_2/gazebo_pose</topicName>
        <gaussianNoise>0.00</gaussianNoise>
        <frameName>world</frameName>
        <xyzOffsets>0 0 0</xyzOffsets>
        <rpyOffsets>0 0 0</rpyOffsets>
      </plugin>
      <frame name='fake_ugv2::camera_front::__model__' attached_to='fake_ugv2::camera_front::Monocular_front_link'>
        <pose relative_to='fake_ugv2::__model__'>0.12 0 0.025 0 -0 0</pose>
      </frame>
      <link name='fake_ugv2::camera_front::Monocular_front_link'>
        <inertial>
          <mass>0.001</mass>
          <inertia>
            <ixx>1e-06</ixx>
            <ixy>0</ixy>
            <ixz>0</ixz>
            <iyy>1e-06</iyy>
            <iyz>0</iyz>
            <izz>1e-06</izz>
          </inertia>
        </inertial>
        <visual name='visual'>
          <geometry>
            <box>
              <size>0.01 0.01 0.01</size>
            </box>
          </geometry>
        </visual>
        <collision name='collision'>
          <pose>0 0 0 0 -0 0</pose>
          <geometry>
            <box>
              <size>0.01 0.01 0.01</size>
            </box>
          </geometry>
          <max_contacts>10</max_contacts>
          <surface>
            <contact>
              <ode/>
            </contact>
            <bounce/>
            <friction>
              <torsional>
                <ode/>
              </torsional>
              <ode/>
            </friction>
          </surface>
        </collision>
        <sensor name='camera' type='camera'>
          <camera name='__default__'>
            <horizontal_fov>1.239</horizontal_fov>
            <image>
              <width>640</width>
              <height>480</height>
            </image>
            <clip>
              <near>0.1</near>
              <far>100</far>
            </clip>
            <noise>
              <type>gaussian</type>
              <mean>0</mean>
              <stddev>0.001</stddev>
            </noise>
          </camera>
          <always_on>1</always_on>
          <update_rate>30</update_rate>
          <visualize>0</visualize>
          <plugin name='camera_plugin' filename='libgazebo_ros_camera.so'>
            <robotNamespace/>
            <alwaysOn>1</alwaysOn>
            <imageTopicName>image_raw</imageTopicName>
            <cameraInfoTopicName>camera_info</cameraInfoTopicName>
            <updateRate>30.0</updateRate>
            <cameraName>monocular_front</cameraName>
            <frameName>/monocular_front_link</frameName>
            <CxPrime>320</CxPrime>
            <Cx>320</Cx>
            <Cy>240</Cy>
            <hackBaseline>0</hackBaseline>
            <focalLength>448.710659</focalLength>
            <distortionK1>0.0</distortionK1>
            <distortionK2>0.0</distortionK2>
            <distortionK3>0.0</distortionK3>
            <distortionT1>0.0</distortionT1>
            <distortionT2>0.0</distortionT2>
          </plugin>
        </sensor>
        <self_collide>0</self_collide>
        <kinematic>0</kinematic>
        <pose relative_to='fake_ugv2::camera_front::__model__'>0 0 0 0 -0 0</pose>
        <enable_wind>0</enable_wind>
      </link>
      <joint name='fake_ugv2::Monocular_front_joint' type='fixed'>
        <child>fake_ugv2::camera_front::Monocular_front_link</child>
        <parent>fake_ugv2::base_link</parent>
        <axis>
          <xyz>0 0 1</xyz>
          <limit>
            <upper>0</upper>
            <lower>0</lower>
          </limit>
        </axis>
      </joint>
    </model>
    <model name='ugv_3'>
      <frame name='fake_ugv3::__model__' attached_to='fake_ugv3::base_link'>
        <pose relative_to='__model__'>0 0 0 0 -0 0</pose>
      </frame>
      <static>1</static>
      <link name='fake_ugv3::base_link'>
        <pose relative_to='fake_ugv3::__model__'>0 0 0 0 -0 0</pose>
        <visual name='odom_fixed_joint_lump__base_link_visual'>
          <pose>0 0 0 0 -0 0</pose>
          <geometry>
            <mesh>
              <scale>1 1 1</scale>
              <uri>model://fake_ugv3/meshes/chassis_link.STL</uri>
            </mesh>
          </geometry>
          <material>
            <script>
              <name>Gazebo/Grey</name>
              <uri>file://media/materials/scripts/gazebo.material</uri>
            </script>
          </material>
        </visual>
        <visual name='odom_fixed_joint_lump__top_link_visual_1'>
          <pose>0 0 0.114486 0 -0 0</pose>
          <geometry>
            <mesh>
              <scale>1 1 1</scale>
              <uri>model://fake_ugv3/meshes/top_link.STL</uri>
            </mesh>
          </geometry>
          <material>
            <script>
              <name>Gazebo/ZincYellow</name>
              <uri>file://media/materials/scripts/gazebo.material</uri>
            </script>
          </material>
        </visual>
        <visual name='odom_fixed_joint_lump__battery_link_visual_2'>
          <pose>-0.09302 -0.000128 0.114486 0 -0 0</pose>
          <geometry>
            <mesh>
              <scale>1 1 1</scale>
              <uri>model://fake_ugv3/meshes/battery_link.STL</uri>
            </mesh>
          </geometry>
          <material>
            <script>
              <name>Gazebo/FlatBlack</name>
              <uri>file://media/materials/scripts/gazebo.material</uri>
            </script>
          </material>
        </visual>
        <visual name='odom_fixed_joint_lump__housing_link_visual_3'>
          <pose>0.03473 0 0.114486 0 -0 0</pose>
          <geometry>
            <mesh>
              <scale>1 1 1</scale>
              <uri>model://fake_ugv3/meshes/housing_link.STL</uri>
            </mesh>
          </geometry>
          <material>
            <script>
              <name>Gazebo/FlatBlack</name>
              <uri>file://media/materials/scripts/gazebo.material</uri>
            </script>
          </material>
        </visual>
        <visual name='odom_fixed_joint_lump__l_antenna_link_visual_4'>
          <pose>-0.1565 0.0762 0.114486 0 -0 0</pose>
          <geometry>
            <mesh>
              <scale>1 1 1</scale>
              <uri>model://fake_ugv3/meshes/antenna_link.STL</uri>
            </mesh>
          </geometry>
          <material>
            <script>
              <name>Gazebo/FlatBlack</name>
              <uri>file://media/materials/scripts/gazebo.material</uri>
            </script>
          </material>
        </visual>
        <visual name='odom_fixed_joint_lump__r_antenna_link_visual_5'>
          <pose>-0.1565 -0.0762 0.114486 0 -0 0</pose>
          <geometry>
            <mesh>
              <scale>1 1 1</scale>
              <uri>model://fake_ugv3/meshes/antenna_link.STL</uri>
            </mesh>
          </geometry>
          <material>
            <script>
              <name>Gazebo/FlatBlack</name>
              <uri>file://media/materials/scripts/gazebo.material</uri>
            </script>
          </material>
        </visual>
        <gravity>1</gravity>
        <velocity_decay/>
        <self_collide>0</self_collide>
        <enable_wind>0</enable_wind>
        <kinematic>0</kinematic>
      </link>
      <link name='fake_ugv3::lb_wheel_link'>
        <pose relative_to='fake_ugv3::__model__'>-0.15 0.16317 0.0215 0 -0 0</pose>
        <visual name='lb_wheel_link_visual'>
          <pose>0 0 0 0 -0 0</pose>
          <geometry>
            <mesh>
              <scale>1 1 1</scale>
              <uri>model://fake_ugv3/meshes/wheel_link.STL</uri>
            </mesh>
          </geometry>
          <material>
            <script>
              <name>Gazebo/FlatBlack</name>
              <uri>file://media/materials/scripts/gazebo.material</uri>
            </script>
          </material>
        </visual>
        <gravity>1</gravity>
        <velocity_decay/>
        <self_collide>0</self_collide>
        <enable_wind>0</enable_wind>
        <kinematic>0</kinematic>
      </link>
      <joint name='fake_ugv3::lb_wheel_joint' type='revolute'>
        <child>fake_ugv3::lb_wheel_link</child>
        <parent>fake_ugv3::base_link</parent>
        <axis>
          <xyz expressed_in='fake_ugv3::__model__'>0 1 0</xyz>
          <limit>
            <lower>-1e+16</lower>
            <upper>1e+16</upper>
          </limit>
          <dynamics>
            <spring_reference>0</spring_reference>
            <spring_stiffness>0</spring_stiffness>
          </dynamics>
        </axis>
      </joint>
      <link name='fake_ugv3::lf_wheel_link'>
        <pose relative_to='fake_ugv3::__model__'>0.15 0.16317 0.0215 0 -0 0</pose>
        <visual name='lf_wheel_link_visual'>
          <pose>0 0 0 0 -0 0</pose>
          <geometry>
            <mesh>
              <scale>1 1 1</scale>
              <uri>model://fake_ugv3/meshes/wheel_link.STL</uri>
            </mesh>
          </geometry>
          <material>
            <script>
              <name>Gazebo/FlatBlack</name>
              <uri>file://media/materials/scripts/gazebo.material</uri>
            </script>
          </material>
        </visual>
        <gravity>1</gravity>
        <velocity_decay/>
        <self_collide>0</self_collide>
        <enable_wind>0</enable_wind>
        <kinematic>0</kinematic>
      </link>
      <joint name='fake_ugv3::lf_wheel_joint' type='revolute'>
        <child>fake_ugv3::lf_wheel_link</child>
        <parent>fake_ugv3::base_link</parent>
        <axis>
          <xyz expressed_in='fake_ugv3::__model__'>0 1 0</xyz>
          <limit>
            <lower>-1e+16</lower>
            <upper>1e+16</upper>
          </limit>
          <dynamics>
            <spring_reference>0</spring_reference>
            <spring_stiffness>0</spring_stiffness>
          </dynamics>
        </axis>
      </joint>
      <link name='fake_ugv3::rb_wheel_link'>
        <pose relative_to='fake_ugv3::__model__'>-0.15 -0.16317 0.0215 0 -0 0</pose>
        <visual name='rb_wheel_link_visual'>
          <pose>0 0 0 0 -0 0</pose>
          <geometry>
            <mesh>
              <scale>1 1 1</scale>
              <uri>model://fake_ugv3/meshes/wheel_link.STL</uri>
            </mesh>
          </geometry>
          <material>
            <script>
              <name>Gazebo/FlatBlack</name>
              <uri>file://media/materials/scripts/gazebo.material</uri>
            </script>
          </material>
        </visual>
        <gravity>1</gravity>
        <velocity_decay/>
        <self_collide>0</self_collide>
        <enable_wind>0</enable_wind>
        <kinematic>0</kinematic>
      </link>
      <joint name='fake_ugv3::rb_wheel_joint' type='revolute'>
        <child>fake_ugv3::rb_wheel_link</child>
        <parent>fake_ugv3::base_link</parent>
        <axis>
          <xyz expressed_in='fake_ugv3::__model__'>0 1 0</xyz>
          <limit>
            <lower>-1e+16</lower>
            <upper>1e+16</upper>
          </limit>
          <dynamics>
            <spring_reference>0</spring_reference>
            <spring_stiffness>0</spring_stiffness>
          </dynamics>
        </axis>
      </joint>
      <link name='fake_ugv3::rf_wheel_link'>
        <pose relative_to='fake_ugv3::__model__'>0.15 -0.16317 0.0215 0 -0 0</pose>
        <visual name='rf_wheel_link_visual'>
          <pose>0 0 0 0 -0 0</pose>
          <geometry>
            <mesh>
              <scale>1 1 1</scale>
              <uri>model://fake_ugv3/meshes/wheel_link.STL</uri>
            </mesh>
          </geometry>
          <material>
            <script>
              <name>Gazebo/FlatBlack</name>
              <uri>file://media/materials/scripts/gazebo.material</uri>
            </script>
          </material>
        </visual>
        <gravity>1</gravity>
        <velocity_decay/>
        <self_collide>0</self_collide>
        <enable_wind>0</enable_wind>
        <kinematic>0</kinematic>
      </link>
      <joint name='fake_ugv3::rf_wheel_joint' type='revolute'>
        <child>fake_ugv3::rf_wheel_link</child>
        <parent>fake_ugv3::base_link</parent>
        <axis>
          <xyz expressed_in='fake_ugv3::__model__'>0 1 0</xyz>
          <limit>
            <lower>-1e+16</lower>
            <upper>1e+16</upper>
          </limit>
          <dynamics>
            <spring_reference>0</spring_reference>
            <spring_stiffness>0</spring_stiffness>
          </dynamics>
        </axis>
      </joint>
      <plugin name='p3d_base_controller' filename='libgazebo_ros_p3d.so'>
        <alwaysOn>1</alwaysOn>
        <updateRate>50.0</updateRate>
        <bodyName>fake_ugv3::base_link</bodyName>
        <topicName>/ugv_3/gazebo_pose</topicName>
        <gaussianNoise>0.00</gaussianNoise>
        <frameName>world</frameName>
        <xyzOffsets>0 0 0</xyzOffsets>
        <rpyOffsets>0 0 0</rpyOffsets>
      </plugin>
      <frame name='fake_ugv3::camera_front::__model__' attached_to='fake_ugv3::camera_front::Monocular_front_link'>
        <pose relative_to='fake_ugv3::__model__'>0.12 0 0.025 0 -0 0</pose>
      </frame>
      <link name='fake_ugv3::camera_front::Monocular_front_link'>
        <inertial>
          <mass>0.001</mass>
          <inertia>
            <ixx>1e-06</ixx>
            <ixy>0</ixy>
            <ixz>0</ixz>
            <iyy>1e-06</iyy>
            <iyz>0</iyz>
            <izz>1e-06</izz>
          </inertia>
        </inertial>
        <visual name='visual'>
          <geometry>
            <box>
              <size>0.01 0.01 0.01</size>
            </box>
          </geometry>
        </visual>
        <collision name='collision'>
          <pose>0 0 0 0 -0 0</pose>
          <geometry>
            <box>
              <size>0.01 0.01 0.01</size>
            </box>
          </geometry>
          <max_contacts>10</max_contacts>
          <surface>
            <contact>
              <ode/>
            </contact>
            <bounce/>
            <friction>
              <torsional>
                <ode/>
              </torsional>
              <ode/>
            </friction>
          </surface>
        </collision>
        <sensor name='camera' type='camera'>
          <camera name='__default__'>
            <horizontal_fov>1.239</horizontal_fov>
            <image>
              <width>640</width>
              <height>480</height>
            </image>
            <clip>
              <near>0.1</near>
              <far>100</far>
            </clip>
            <noise>
              <type>gaussian</type>
              <mean>0</mean>
              <stddev>0.001</stddev>
            </noise>
          </camera>
          <always_on>1</always_on>
          <update_rate>30</update_rate>
          <visualize>0</visualize>
          <plugin name='camera_plugin' filename='libgazebo_ros_camera.so'>
            <robotNamespace/>
            <alwaysOn>1</alwaysOn>
            <imageTopicName>image_raw</imageTopicName>
            <cameraInfoTopicName>camera_info</cameraInfoTopicName>
            <updateRate>30.0</updateRate>
            <cameraName>monocular_front</cameraName>
            <frameName>/monocular_front_link</frameName>
            <CxPrime>320</CxPrime>
            <Cx>320</Cx>
            <Cy>240</Cy>
            <hackBaseline>0</hackBaseline>
            <focalLength>448.710659</focalLength>
            <distortionK1>0.0</distortionK1>
            <distortionK2>0.0</distortionK2>
            <distortionK3>0.0</distortionK3>
            <distortionT1>0.0</distortionT1>
            <distortionT2>0.0</distortionT2>
          </plugin>
        </sensor>
        <self_collide>0</self_collide>
        <kinematic>0</kinematic>
        <pose relative_to='fake_ugv3::camera_front::__model__'>0 0 0 0 -0 0</pose>
        <enable_wind>0</enable_wind>
      </link>
      <joint name='fake_ugv3::Monocular_front_joint' type='fixed'>
        <child>fake_ugv3::camera_front::Monocular_front_link</child>
        <parent>fake_ugv3::base_link</parent>
        <axis>
          <xyz>0 0 1</xyz>
          <limit>
            <upper>0</upper>
            <lower>0</lower>
          </limit>
        </axis>
      </joint>
    </model>
    <gravity>0 0 -9.8</gravity>
    <magnetic_field>6e-06 2.3e-05 -4.2e-05</magnetic_field>
    <atmosphere type='adiabatic'/>
    <scene>
      <ambient>0.4 0.4 0.4 1</ambient>
      <background>0.7 0.7 0.7 1</background>
      <shadows>1</shadows>
    </scene>
    <wind/>
    <spherical_coordinates>
      <surface_model>EARTH_WGS84</surface_model>
      <latitude_deg>0</latitude_deg>
      <longitude_deg>0</longitude_deg>
      <elevation>0</elevation>
      <heading_deg>0</heading_deg>
    </spherical_coordinates>
    <model name='House 1'>
      <static>1</static>
      <link name='link'>
        <collision name='collision'>
          <geometry>
            <mesh>
              <uri>model://house_1/meshes/house_1.dae</uri>
              <scale>1.5 1.5 1.5</scale>
            </mesh>
          </geometry>
          <max_contacts>10</max_contacts>
          <surface>
            <contact>
              <ode/>
            </contact>
            <bounce/>
            <friction>
              <torsional>
                <ode/>
              </torsional>
              <ode/>
            </friction>
          </surface>
        </collision>
        <visual name='visual'>
          <geometry>
            <mesh>
              <uri>model://house_1/meshes/house_1.dae</uri>
              <scale>1.5 1.5 1.5</scale>
            </mesh>
          </geometry>
          <material>
            <script>
              <uri>model://house_1/materials/scripts</uri>
              <uri>model://house_1/materials/textures</uri>
              <name>House_1/Diffuse</name>
            </script>
            <shader type='normal_map_tangent_space'>
              <normal_map>House_1_Normal.png</normal_map>
            </shader>
          </material>
        </visual>
        <self_collide>0</self_collide>
        <enable_wind>0</enable_wind>
        <kinematic>0</kinematic>
      </link>
      <pose>10.2972 7.96415 0 0 -0 0</pose>
    </model>
    <model name='House 1_0'>
      <static>1</static>
      <link name='link'>
        <collision name='collision'>
          <geometry>
            <mesh>
              <uri>model://house_1/meshes/house_1.dae</uri>
              <scale>1.5 1.5 1.5</scale>
            </mesh>
          </geometry>
          <max_contacts>10</max_contacts>
          <surface>
            <contact>
              <ode/>
            </contact>
            <bounce/>
            <friction>
              <torsional>
                <ode/>
              </torsional>
              <ode/>
            </friction>
          </surface>
        </collision>
        <visual name='visual'>
          <geometry>
            <mesh>
              <uri>model://house_1/meshes/house_1.dae</uri>
              <scale>1.5 1.5 1.5</scale>
            </mesh>
          </geometry>
          <material>
            <script>
              <uri>model://house_1/materials/scripts</uri>
              <uri>model://house_1/materials/textures</uri>
              <name>House_1/Diffuse</name>
            </script>
            <shader type='normal_map_tangent_space'>
              <normal_map>House_1_Normal.png</normal_map>
            </shader>
          </material>
        </visual>
        <self_collide>0</self_collide>
        <enable_wind>0</enable_wind>
        <kinematic>0</kinematic>
      </link>
      <pose>29.5393 7.48207 0 0 -0 0</pose>
    </model>
    <model name='House 1_1'>
      <static>1</static>
      <link name='link'>
        <collision name='collision'>
          <geometry>
            <mesh>
              <uri>model://house_1/meshes/house_1.dae</uri>
              <scale>1.5 1.5 1.5</scale>
            </mesh>
          </geometry>
          <max_contacts>10</max_contacts>
          <surface>
            <contact>
              <ode/>
            </contact>
            <bounce/>
            <friction>
              <torsional>
                <ode/>
              </torsional>
              <ode/>
            </friction>
          </surface>
        </collision>
        <visual name='visual'>
          <geometry>
            <mesh>
              <uri>model://house_1/meshes/house_1.dae</uri>
              <scale>1.5 1.5 1.5</scale>
            </mesh>
          </geometry>
          <material>
            <script>
              <uri>model://house_1/materials/scripts</uri>
              <uri>model://house_1/materials/textures</uri>
              <name>House_1/Diffuse</name>
            </script>
            <shader type='normal_map_tangent_space'>
              <normal_map>House_1_Normal.png</normal_map>
            </shader>
          </material>
        </visual>
        <self_collide>0</self_collide>
        <enable_wind>0</enable_wind>
        <kinematic>0</kinematic>
      </link>
      <pose>-10.615 8.7783 0 0 -0 0</pose>
    </model>
    <model name='House 1_2'>
      <static>1</static>
      <link name='link'>
        <collision name='collision'>
          <geometry>
            <mesh>
              <uri>model://house_1/meshes/house_1.dae</uri>
              <scale>1.5 1.5 1.5</scale>
            </mesh>
          </geometry>
          <max_contacts>10</max_contacts>
          <surface>
            <contact>
              <ode/>
            </contact>
            <bounce/>
            <friction>
              <torsional>
                <ode/>
              </torsional>
              <ode/>
            </friction>
          </surface>
        </collision>
        <visual name='visual'>
          <geometry>
            <mesh>
              <uri>model://house_1/meshes/house_1.dae</uri>
              <scale>1.5 1.5 1.5</scale>
            </mesh>
          </geometry>
          <material>
            <script>
              <uri>model://house_1/materials/scripts</uri>
              <uri>model://house_1/materials/textures</uri>
              <name>House_1/Diffuse</name>
            </script>
            <shader type='normal_map_tangent_space'>
              <normal_map>House_1_Normal.png</normal_map>
            </shader>
          </material>
        </visual>
        <self_collide>0</self_collide>
        <enable_wind>0</enable_wind>
        <kinematic>0</kinematic>
      </link>
      <pose>-30.0142 9.95053 0 0 -0 0</pose>
    </model>
    <model name='school'>
      <static>1</static>
      <link name='link'>
        <collision name='collision'>
          <geometry>
            <mesh>
              <uri>model://school/meshes/school.dae</uri>
            </mesh>
          </geometry>
          <max_contacts>10</max_contacts>
          <surface>
            <contact>
              <ode/>
            </contact>
            <bounce/>
            <friction>
              <torsional>
                <ode/>
              </torsional>
              <ode/>
            </friction>
          </surface>
        </collision>
        <visual name='visual'>
          <geometry>
            <mesh>
              <uri>model://school/meshes/school.dae</uri>
            </mesh>
          </geometry>
        </visual>
        <self_collide>0</self_collide>
        <enable_wind>0</enable_wind>
        <kinematic>0</kinematic>
      </link>
      <pose>21.9475 -20.3777 0 0 -0 0</pose>
    </model>
    <model name='robocup_3d_field'>
      <static>1</static>
      <link name='field'>
        <pose>0 0 0.01 0 -0 0</pose>
        <collision name='collision'>
          <geometry>
            <plane>
              <normal>0 0 1</normal>
              <size>30 20</size>
            </plane>
          </geometry>
          <surface>
            <friction>
              <ode>
                <mu>100</mu>
                <mu2>50</mu2>
              </ode>
              <torsional>
                <ode/>
              </torsional>
            </friction>
            <contact>
              <ode/>
            </contact>
            <bounce/>
          </surface>
          <max_contacts>10</max_contacts>
        </collision>
        <visual name='base1'>
          <pose>0 11 0.001 0 -0 0</pose>
          <cast_shadows>0</cast_shadows>
          <geometry>
            <plane>
              <normal>0 0 1</normal>
              <size>34 2</size>
            </plane>
          </geometry>
          <material>
            <script>
              <uri>model://robocup_3Dsim_field/materials/scripts/</uri>
              <uri>model://robocup_3Dsim_field/materials/textures/</uri>
              <name>RoboCup/FieldBorder</name>
            </script>
          </material>
        </visual>
        <visual name='base2'>
          <pose>0 -11 0.001 0 -0 0</pose>
          <cast_shadows>0</cast_shadows>
          <geometry>
            <plane>
              <normal>0 0 1</normal>
              <size>34 2</size>
            </plane>
          </geometry>
          <material>
            <script>
              <uri>model://robocup_3Dsim_field/materials/scripts/</uri>
              <uri>model://robocup_3Dsim_field/materials/textures/</uri>
              <name>RoboCup/FieldBorder</name>
            </script>
          </material>
        </visual>
        <visual name='base3'>
          <pose>16 0 0.001 0 -0 0</pose>
          <cast_shadows>0</cast_shadows>
          <geometry>
            <plane>
              <normal>0 0 1</normal>
              <size>2 20</size>
            </plane>
          </geometry>
          <material>
            <script>
              <uri>model://robocup_3Dsim_field/materials/scripts/</uri>
              <uri>model://robocup_3Dsim_field/materials/textures/</uri>
              <name>RoboCup/FieldBorder</name>
            </script>
          </material>
        </visual>
        <visual name='base4'>
          <pose>-16 0 0.001 0 -0 0</pose>
          <cast_shadows>0</cast_shadows>
          <geometry>
            <plane>
              <normal>0 0 1</normal>
              <size>2 20</size>
            </plane>
          </geometry>
          <material>
            <script>
              <uri>model://robocup_3Dsim_field/materials/scripts/</uri>
              <uri>model://robocup_3Dsim_field/materials/textures/</uri>
              <name>RoboCup/FieldBorder</name>
            </script>
          </material>
        </visual>
        <visual name='carpet'>
          <cast_shadows>0</cast_shadows>
          <geometry>
            <plane>
              <normal>0 0 1</normal>
              <size>30 20</size>
            </plane>
          </geometry>
          <material>
            <script>
              <uri>model://robocup_3Dsim_field/materials/scripts/</uri>
              <uri>model://robocup_3Dsim_field/materials/textures/</uri>
              <name>RoboCup/Grass</name>
            </script>
          </material>
        </visual>
        <self_collide>0</self_collide>
        <enable_wind>0</enable_wind>
        <kinematic>0</kinematic>
      </link>
      <pose>-8.76606 -28.1961 0 0 -0 0</pose>
    </model>
    <model name='House 1_3'>
      <static>1</static>
      <link name='link'>
        <collision name='collision'>
          <geometry>
            <mesh>
              <uri>model://house_1/meshes/house_1.dae</uri>
              <scale>1.5 1.5 1.5</scale>
            </mesh>
          </geometry>
          <max_contacts>10</max_contacts>
          <surface>
            <contact>
              <ode/>
            </contact>
            <bounce/>
            <friction>
              <torsional>
                <ode/>
              </torsional>
              <ode/>
            </friction>
          </surface>
        </collision>
        <visual name='visual'>
          <geometry>
            <mesh>
              <uri>model://house_1/meshes/house_1.dae</uri>
              <scale>1.5 1.5 1.5</scale>
            </mesh>
          </geometry>
          <material>
            <script>
              <uri>model://house_1/materials/scripts</uri>
              <uri>model://house_1/materials/textures</uri>
              <name>House_1/Diffuse</name>
            </script>
            <shader type='normal_map_tangent_space'>
              <normal_map>House_1_Normal.png</normal_map>
            </shader>
          </material>
        </visual>
        <self_collide>0</self_collide>
        <enable_wind>0</enable_wind>
        <kinematic>0</kinematic>
      </link>
      <pose>28.5645 36.403 0 0 -0 0</pose>
    </model>
    <model name='House 1_4'>
      <static>1</static>
      <link name='link'>
        <collision name='collision'>
          <geometry>
            <mesh>
              <uri>model://house_1/meshes/house_1.dae</uri>
              <scale>1.5 1.5 1.5</scale>
            </mesh>
          </geometry>
          <max_contacts>10</max_contacts>
          <surface>
            <contact>
              <ode/>
            </contact>
            <bounce/>
            <friction>
              <torsional>
                <ode/>
              </torsional>
              <ode/>
            </friction>
          </surface>
        </collision>
        <visual name='visual'>
          <geometry>
            <mesh>
              <uri>model://house_1/meshes/house_1.dae</uri>
              <scale>1.5 1.5 1.5</scale>
            </mesh>
          </geometry>
          <material>
            <script>
              <uri>model://house_1/materials/scripts</uri>
              <uri>model://house_1/materials/textures</uri>
              <name>House_1/Diffuse</name>
            </script>
            <shader type='normal_map_tangent_space'>
              <normal_map>House_1_Normal.png</normal_map>
            </shader>
          </material>
        </visual>
        <self_collide>0</self_collide>
        <enable_wind>0</enable_wind>
        <kinematic>0</kinematic>
      </link>
      <pose>9.27874 36.4674 0 0 -0 0</pose>
    </model>
    <model name='House 1_5'>
      <static>1</static>
      <link name='link'>
        <collision name='collision'>
          <geometry>
            <mesh>
              <uri>model://house_1/meshes/house_1.dae</uri>
              <scale>1.5 1.5 1.5</scale>
            </mesh>
          </geometry>
          <max_contacts>10</max_contacts>
          <surface>
            <contact>
              <ode/>
            </contact>
            <bounce/>
            <friction>
              <torsional>
                <ode/>
              </torsional>
              <ode/>
            </friction>
          </surface>
        </collision>
        <visual name='visual'>
          <geometry>
            <mesh>
              <uri>model://house_1/meshes/house_1.dae</uri>
              <scale>1.5 1.5 1.5</scale>
            </mesh>
          </geometry>
          <material>
            <script>
              <uri>model://house_1/materials/scripts</uri>
              <uri>model://house_1/materials/textures</uri>
              <name>House_1/Diffuse</name>
            </script>
            <shader type='normal_map_tangent_space'>
              <normal_map>House_1_Normal.png</normal_map>
            </shader>
          </material>
        </visual>
        <self_collide>0</self_collide>
        <enable_wind>0</enable_wind>
        <kinematic>0</kinematic>
      </link>
      <pose>-12.6299 37.2565 0 0 -0 0</pose>
    </model>
    <model name='House 1_6'>
      <static>1</static>
      <link name='link'>
        <collision name='collision'>
          <geometry>
            <mesh>
              <uri>model://house_1/meshes/house_1.dae</uri>
              <scale>1.5 1.5 1.5</scale>
            </mesh>
          </geometry>
          <max_contacts>10</max_contacts>
          <surface>
            <contact>
              <ode/>
            </contact>
            <bounce/>
            <friction>
              <torsional>
                <ode/>
              </torsional>
              <ode/>
            </friction>
          </surface>
        </collision>
        <visual name='visual'>
          <geometry>
            <mesh>
              <uri>model://house_1/meshes/house_1.dae</uri>
              <scale>1.5 1.5 1.5</scale>
            </mesh>
          </geometry>
          <material>
            <script>
              <uri>model://house_1/materials/scripts</uri>
              <uri>model://house_1/materials/textures</uri>
              <name>House_1/Diffuse</name>
            </script>
            <shader type='normal_map_tangent_space'>
              <normal_map>House_1_Normal.png</normal_map>
            </shader>
          </material>
        </visual>
        <self_collide>0</self_collide>
        <enable_wind>0</enable_wind>
        <kinematic>0</kinematic>
      </link>
      <pose>-32.9292 38.0402 0 0 -0 0</pose>
    </model>
    <state world_name='default'>
      <sim_time>137 424000000</sim_time>
      <real_time>137 845832255</real_time>
      <wall_time>1760346332 603302287</wall_time>
      <iterations>137424</iterations>
      <model name='House 1'>
        <pose>10.2972 7.96415 0 0 -0 0</pose>
        <scale>1 1 1</scale>
        <link name='link'>
          <pose>10.2972 7.96415 0 0 -0 0</pose>
          <velocity>0 0 0 0 -0 0</velocity>
          <acceleration>0 0 0 0 -0 0</acceleration>
          <wrench>0 0 0 0 -0 0</wrench>
        </link>
      </model>
      <model name='House 1_0'>
        <pose>29.5393 7.48207 0 0 -0 0</pose>
        <scale>1 1 1</scale>
        <link name='link'>
          <pose>29.5393 7.48207 0 0 -0 0</pose>
          <velocity>0 0 0 0 -0 0</velocity>
          <acceleration>0 0 0 0 -0 0</acceleration>
          <wrench>0 0 0 0 -0 0</wrench>
        </link>
      </model>
      <model name='House 1_1'>
        <pose>-10.615 8.7783 0 0 -0 0</pose>
        <scale>1 1 1</scale>
        <link name='link'>
          <pose>-10.615 8.7783 0 0 -0 0</pose>
          <velocity>0 0 0 0 -0 0</velocity>
          <acceleration>0 0 0 0 -0 0</acceleration>
          <wrench>0 0 0 0 -0 0</wrench>
        </link>
      </model>
      <model name='House 1_2'>
        <pose>-30.0142 9.95053 0 0 -0 0</pose>
        <scale>1 1 1</scale>
        <link name='link'>
          <pose>-30.0142 9.95053 0 0 -0 0</pose>
          <velocity>0 0 0 0 -0 0</velocity>
          <acceleration>0 0 0 0 -0 0</acceleration>
          <wrench>0 0 0 0 -0 0</wrench>
        </link>
      </model>
      <model name='House 1_3'>
        <pose>28.5645 36.403 0 0 -0 0</pose>
        <scale>1 1 1</scale>
        <link name='link'>
          <pose>28.5645 36.403 0 0 -0 0</pose>
          <velocity>0 0 0 0 -0 0</velocity>
          <acceleration>0 0 0 0 -0 0</acceleration>
          <wrench>0 0 0 0 -0 0</wrench>
        </link>
      </model>
      <model name='House 1_4'>
        <pose>9.27874 36.4674 0 0 -0 0</pose>
        <scale>1 1 1</scale>
        <link name='link'>
          <pose>9.27874 36.4674 0 0 -0 0</pose>
          <velocity>0 0 0 0 -0 0</velocity>
          <acceleration>0 0 0 0 -0 0</acceleration>
          <wrench>0 0 0 0 -0 0</wrench>
        </link>
      </model>
      <model name='House 1_5'>
        <pose>-12.6299 37.2565 0 0 -0 0</pose>
        <scale>1 1 1</scale>
        <link name='link'>
          <pose>-12.6299 37.2565 0 0 -0 0</pose>
          <velocity>0 0 0 0 -0 0</velocity>
          <acceleration>0 0 0 0 -0 0</acceleration>
          <wrench>0 0 0 0 -0 0</wrench>
        </link>
      </model>
      <model name='House 1_6'>
        <pose>-32.9292 38.0402 0 0 -0 0</pose>
        <scale>1 1 1</scale>
        <link name='link'>
          <pose>-32.9292 38.0402 0 0 -0 0</pose>
          <velocity>0 0 0 0 -0 0</velocity>
          <acceleration>0 0 0 0 -0 0</acceleration>
          <wrench>0 0 0 0 -0 0</wrench>
        </link>
      </model>
      <model name='ground_plane'>
        <pose>0 0 0 0 -0 0</pose>
        <scale>1 1 1</scale>
        <link name='link'>
          <pose>0 0 0 0 -0 0</pose>
          <velocity>0 0 0 0 -0 0</velocity>
          <acceleration>0 0 0 0 -0 0</acceleration>
          <wrench>0 0 0 0 -0 0</wrench>
        </link>
      </model>
      <model name='robocup_3d_field'>
        <pose>-8.76606 -28.1961 0 0 -0 0</pose>
        <scale>1 1 1</scale>
        <link name='field'>
          <pose>-8.76606 -28.1961 0.01 0 -0 0</pose>
          <velocity>0 0 0 0 -0 0</velocity>
          <acceleration>0 0 0 0 -0 0</acceleration>
          <wrench>0 0 0 0 -0 0</wrench>
        </link>
      </model>
      <model name='school'>
        <pose>21.9475 -30 0 0 0 -1.57</pose>
        <scale>1 1 1</scale>
        <link name='link'>
          <pose>21.9475 -30 0 0 0 -1.57</pose>
          <velocity>0 0 0 0 -0 0</velocity>
          <acceleration>0 0 0 0 -0 0</acceleration>
          <wrench>0 0 0 0 -0 0</wrench>
        </link>
      </model>
      <model name='uav_1'>
        <pose>67.025 0 0 0 -0 0</pose>
        <scale>1 1 1</scale>
        <link name='fake_uav1::base_link'>
          <pose>67.025 0 0 0 -0 0</pose>
          <velocity>0 0 0 0 -0 0</velocity>
          <acceleration>0 0 0 0 -0 0</acceleration>
          <wrench>0 0 0 0 -0 0</wrench>
        </link>
        <link name='fake_uav1::camera_down::Monocular_down_link'>
          <pose>67.015 0 -0.02 0.001593 1.57079 3.14159</pose>
          <velocity>0 0 0 0 -0 0</velocity>
          <acceleration>0 0 0 0 -0 0</acceleration>
          <wrench>0 0 0 0 -0 0</wrench>
        </link>
        <link name='fake_uav1::camera_front::Monocular_front_link'>
          <pose>67.145 0 0.025 0 -0 0</pose>
          <velocity>0 0 0 0 -0 0</velocity>
          <acceleration>0 0 0 0 -0 0</acceleration>
          <wrench>0 0 0 0 -0 0</wrench>
        </link>
        <link name='fake_uav1::livox_mid360::base_link'>
          <pose>67.061 -0.0155 0.075 0 -0 0</pose>
          <velocity>0 0 0 0 -0 0</velocity>
          <acceleration>0 0 0 0 -0 0</acceleration>
          <wrench>0 0 0 0 -0 0</wrench>
        </link>
        <link name='fake_uav1::rotor_0'>
          <pose>67.09 -0.065 -0.025 0 -0 0</pose>
          <velocity>0 0 0 0 -0 0</velocity>
          <acceleration>0 0 0 0 -0 0</acceleration>
          <wrench>0 0 0 0 -0 0</wrench>
        </link>
        <link name='fake_uav1::rotor_1'>
          <pose>66.96 0.065 -0.025 0 -0 0</pose>
          <velocity>0 0 0 0 -0 0</velocity>
          <acceleration>0 0 0 0 -0 0</acceleration>
          <wrench>0 0 0 0 -0 0</wrench>
        </link>
        <link name='fake_uav1::rotor_2'>
          <pose>67.09 0.065 -0.025 0 -0 0</pose>
          <velocity>0 0 0 0 -0 0</velocity>
          <acceleration>0 0 0 0 -0 0</acceleration>
          <wrench>0 0 0 0 -0 0</wrench>
        </link>
        <link name='fake_uav1::rotor_3'>
          <pose>66.96 -0.065 -0.025 0 -0 0</pose>
          <velocity>0 0 0 0 -0 0</velocity>
          <acceleration>0 0 0 0 -0 0</acceleration>
          <wrench>0 0 0 0 -0 0</wrench>
        </link>
      </model>
      <model name='uav_2'>
        <pose>0 0 0 0 -0 2.10311</pose>
        <scale>1 1 1</scale>
        <link name='fake_uav2::base_link'>
          <pose>0 0 0 0 -0 2.10311</pose>
          <velocity>0 0 0 0 -0 0</velocity>
          <acceleration>0 0 0 0 -0 0</acceleration>
          <wrench>0 0 0 0 -0 0</wrench>
        </link>
        <link name='fake_uav2::camera_down::Monocular_down_link'>
          <pose>0.005075 -0.008616 -0.02 0.001593 1.57079 -1.03849</pose>
          <velocity>0 0 0 0 -0 0</velocity>
          <acceleration>0 0 0 0 -0 0</acceleration>
          <wrench>0 0 0 0 -0 0</wrench>
        </link>
        <link name='fake_uav2::camera_front::Monocular_front_link'>
          <pose>-0.060903 0.103396 0.025 0 -0 2.10311</pose>
          <velocity>0 0 0 0 -0 0</velocity>
          <acceleration>0 0 0 0 -0 0</acceleration>
          <wrench>0 0 0 0 -0 0</wrench>
        </link>
        <link name='fake_uav2::livox_mid360::base_link'>
          <pose>-0.004916 0.038886 0.075 0 -0 2.10311</pose>
          <velocity>0 0 0 0 -0 0</velocity>
          <acceleration>0 0 0 0 -0 0</acceleration>
          <wrench>0 0 0 0 -0 0</wrench>
        </link>
        <link name='fake_uav2::rotor_0'>
          <pose>0.023017 0.088996 -0.025 0 -0 2.10311</pose>
          <velocity>0 0 0 0 -0 0</velocity>
          <acceleration>0 0 0 0 -0 0</acceleration>
          <wrench>0 0 0 0 -0 0</wrench>
        </link>
        <link name='fake_uav2::rotor_1'>
          <pose>-0.023017 -0.088996 -0.025 0 -0 2.10311</pose>
          <velocity>0 0 0 0 -0 0</velocity>
          <acceleration>0 0 0 0 -0 0</acceleration>
          <wrench>0 0 0 0 -0 0</wrench>
        </link>
        <link name='fake_uav2::rotor_2'>
          <pose>-0.088996 0.023017 -0.025 0 -0 2.10311</pose>
          <velocity>0 0 0 0 -0 0</velocity>
          <acceleration>0 0 0 0 -0 0</acceleration>
          <wrench>0 0 0 0 -0 0</wrench>
        </link>
        <link name='fake_uav2::rotor_3'>
          <pose>0.088996 -0.023017 -0.025 0 -0 2.10311</pose>
          <velocity>0 0 0 0 -0 0</velocity>
          <acceleration>0 0 0 0 -0 0</acceleration>
          <wrench>0 0 0 0 -0 0</wrench>
        </link>
      </model>
      <model name='uav_3'>
        <pose>0 0 1 0 -0 2.10311</pose>
        <scale>1 1 1</scale>
        <link name='fake_uav3::base_link'>
          <pose>0 0 1 0 -0 2.10311</pose>
          <velocity>0 0 0 0 -0 0</velocity>
          <acceleration>0 0 0 0 -0 0</acceleration>
          <wrench>0 0 0 0 -0 0</wrench>
        </link>
        <link name='fake_uav3::camera_down::Monocular_down_link'>
          <pose>0.005075 -0.008616 0.98 0.001593 1.57079 -1.03849</pose>
          <velocity>0 0 0 0 -0 0</velocity>
          <acceleration>0 0 0 0 -0 0</acceleration>
          <wrench>0 0 0 0 -0 0</wrench>
        </link>
        <link name='fake_uav3::camera_front::Monocular_front_link'>
          <pose>-0.060903 0.103396 1.025 0 -0 2.10311</pose>
          <velocity>0 0 0 0 -0 0</velocity>
          <acceleration>0 0 0 0 -0 0</acceleration>
          <wrench>0 0 0 0 -0 0</wrench>
        </link>
        <link name='fake_uav3::livox_mid360::base_link'>
          <pose>-0.004916 0.038886 1.075 0 -0 2.10311</pose>
          <velocity>0 0 0 0 -0 0</velocity>
          <acceleration>0 0 0 0 -0 0</acceleration>
          <wrench>0 0 0 0 -0 0</wrench>
        </link>
        <link name='fake_uav3::rotor_0'>
          <pose>0.023017 0.088996 0.975 0 -0 2.10311</pose>
          <velocity>0 0 0 0 -0 0</velocity>
          <acceleration>0 0 0 0 -0 0</acceleration>
          <wrench>0 0 0 0 -0 0</wrench>
        </link>
        <link name='fake_uav3::rotor_1'>
          <pose>-0.023017 -0.088996 0.975 0 -0 2.10311</pose>
          <velocity>0 0 0 0 -0 0</velocity>
          <acceleration>0 0 0 0 -0 0</acceleration>
          <wrench>0 0 0 0 -0 0</wrench>
        </link>
        <link name='fake_uav3::rotor_2'>
          <pose>-0.088996 0.023017 0.975 0 -0 2.10311</pose>
          <velocity>0 0 0 0 -0 0</velocity>
          <acceleration>0 0 0 0 -0 0</acceleration>
          <wrench>0 0 0 0 -0 0</wrench>
        </link>
        <link name='fake_uav3::rotor_3'>
          <pose>0.088996 -0.023017 0.975 0 -0 2.10311</pose>
          <velocity>0 0 0 0 -0 0</velocity>
          <acceleration>0 0 0 0 -0 0</acceleration>
          <wrench>0 0 0 0 -0 0</wrench>
        </link>
      </model>
      <model name='ugv_1'>
        <pose>0 0 2 0 -0 2.00311</pose>
        <scale>1 1 1</scale>
        <link name='fake_ugv1::base_link'>
          <pose>0 0 2 0 -0 2.00311</pose>
          <velocity>0 0 0 0 -0 0</velocity>
          <acceleration>0 0 0 0 -0 0</acceleration>
          <wrench>0 0 0 0 -0 0</wrench>
        </link>
        <link name='fake_ugv1::camera_front::Monocular_front_link'>
          <pose>-0.050277 0.10896 2.025 0 -0 2.00311</pose>
          <velocity>0 0 0 0 -0 0</velocity>
          <acceleration>0 0 0 0 -0 0</acceleration>
          <wrench>0 0 0 0 -0 0</wrench>
        </link>
        <link name='fake_ugv1::lb_wheel_link'>
          <pose>-0.085312 -0.204564 2.0215 0 -0 2.00311</pose>
          <velocity>0 0 0 0 -0 0</velocity>
          <acceleration>0 0 0 0 -0 0</acceleration>
          <wrench>0 0 0 0 -0 0</wrench>
        </link>
        <link name='fake_ugv1::lf_wheel_link'>
          <pose>-0.211004 0.067836 2.0215 0 -0 2.00311</pose>
          <velocity>0 0 0 0 -0 0</velocity>
          <acceleration>0 0 0 0 -0 0</acceleration>
          <wrench>0 0 0 0 -0 0</wrench>
        </link>
        <link name='fake_ugv1::rb_wheel_link'>
          <pose>0.211004 -0.067836 2.0215 0 -0 2.00311</pose>
          <velocity>0 0 0 0 -0 0</velocity>
          <acceleration>0 0 0 0 -0 0</acceleration>
          <wrench>0 0 0 0 -0 0</wrench>
        </link>
        <link name='fake_ugv1::rf_wheel_link'>
          <pose>0.085312 0.204564 2.0215 0 -0 2.00311</pose>
          <velocity>0 0 0 0 -0 0</velocity>
          <acceleration>0 0 0 0 -0 0</acceleration>
          <wrench>0 0 0 0 -0 0</wrench>
        </link>
      </model>
      <model name='ugv_2'>
        <pose>0 0 3 0 -0 2.10311</pose>
        <scale>1 1 1</scale>
        <link name='fake_ugv2::base_link'>
          <pose>0 0 3 0 -0 2.10311</pose>
          <velocity>0 0 0 0 -0 0</velocity>
          <acceleration>0 0 0 0 -0 0</acceleration>
          <wrench>0 0 0 0 -0 0</wrench>
        </link>
        <link name='fake_ugv2::camera_front::Monocular_front_link'>
          <pose>-0.060903 0.103396 3.025 0 -0 2.10311</pose>
          <velocity>0 0 0 0 -0 0</velocity>
          <acceleration>0 0 0 0 -0 0</acceleration>
          <wrench>0 0 0 0 -0 0</wrench>
        </link>
        <link name='fake_ugv2::lb_wheel_link'>
          <pose>-0.064464 -0.212059 3.0215 0 -0 2.10311</pose>
          <velocity>0 0 0 0 -0 0</velocity>
          <acceleration>0 0 0 0 -0 0</acceleration>
          <wrench>0 0 0 0 -0 0</wrench>
        </link>
        <link name='fake_ugv2::lf_wheel_link'>
          <pose>-0.216722 0.046432 3.0215 0 -0 2.10311</pose>
          <velocity>0 0 0 0 -0 0</velocity>
          <acceleration>0 0 0 0 -0 0</acceleration>
          <wrench>0 0 0 0 -0 0</wrench>
        </link>
        <link name='fake_ugv2::rb_wheel_link'>
          <pose>0.216722 -0.046432 3.0215 0 -0 2.10311</pose>
          <velocity>0 0 0 0 -0 0</velocity>
          <acceleration>0 0 0 0 -0 0</acceleration>
          <wrench>0 0 0 0 -0 0</wrench>
        </link>
        <link name='fake_ugv2::rf_wheel_link'>
          <pose>0.064464 0.212059 3.0215 0 -0 2.10311</pose>
          <velocity>0 0 0 0 -0 0</velocity>
          <acceleration>0 0 0 0 -0 0</acceleration>
          <wrench>0 0 0 0 -0 0</wrench>
        </link>
      </model>
      <model name='ugv_3'>
        <pose>0 0 4 0 -0 2.10311</pose>
        <scale>1 1 1</scale>
        <link name='fake_ugv3::base_link'>
          <pose>0 0 4 0 -0 2.10311</pose>
          <velocity>0 0 0 0 -0 0</velocity>
          <acceleration>0 0 0 0 -0 0</acceleration>
          <wrench>0 0 0 0 -0 0</wrench>
        </link>
        <link name='fake_ugv3::camera_front::Monocular_front_link'>
          <pose>-0.060903 0.103396 4.025 0 -0 2.10311</pose>
          <velocity>0 0 0 0 -0 0</velocity>
          <acceleration>0 0 0 0 -0 0</acceleration>
          <wrench>0 0 0 0 -0 0</wrench>
        </link>
        <link name='fake_ugv3::lb_wheel_link'>
          <pose>-0.064464 -0.212059 4.0215 0 -0 2.10311</pose>
          <velocity>0 0 0 0 -0 0</velocity>
          <acceleration>0 0 0 0 -0 0</acceleration>
          <wrench>0 0 0 0 -0 0</wrench>
        </link>
        <link name='fake_ugv3::lf_wheel_link'>
          <pose>-0.216722 0.046432 4.0215 0 -0 2.10311</pose>
          <velocity>0 0 0 0 -0 0</velocity>
          <acceleration>0 0 0 0 -0 0</acceleration>
          <wrench>0 0 0 0 -0 0</wrench>
        </link>
        <link name='fake_ugv3::rb_wheel_link'>
          <pose>0.216722 -0.046432 4.0215 0 -0 2.10311</pose>
          <velocity>0 0 0 0 -0 0</velocity>
          <acceleration>0 0 0 0 -0 0</acceleration>
          <wrench>0 0 0 0 -0 0</wrench>
        </link>
        <link name='fake_ugv3::rf_wheel_link'>
          <pose>0.064464 0.212059 4.0215 0 -0 2.10311</pose>
          <velocity>0 0 0 0 -0 0</velocity>
          <acceleration>0 0 0 0 -0 0</acceleration>
          <wrench>0 0 0 0 -0 0</wrench>
        </link>
      </model>
      <light name='sun'>
        <pose>0 0 100 0 -0 0</pose>
      </light>
    </state>
    <gui fullscreen='0'>
      <camera name='user_camera'>
        <pose>-7.46027 -116.488 295.338 -0 1.09758 1.16009</pose>
        <view_controller>orbit</view_controller>
        <projection_type>perspective</projection_type>
      </camera>
    </gui>
  </world>
</sdf>